Workbook

Sheet DATA MTD
B1: PASTE DISINI
B6: WITEL | C6: PRE PI | D6: REGISTERED (RE) | E6: INPROGRESS SC | F6: QC1 | G6: FCC | H6: CANCEL BY FCC | I6: SURVEY NEW MANJA | J6: UN-SC | K6: OGP | Y6: JML COMP (PS) | Z6: CANCEL | AD6: TOTAL CANCEL | AE6: REVOKE | AF6: PI/RE (%) | AG6: PS/RE (%) | AH6: PS/PI (%)
K7: PRE PI | L7: PI | O7: TOTAL PI | P7: FALLOUT | W7: TOTAL FALLOUT | X7: ACT COMP (QC2)
P8: WFM | T8: UIM | U8: ASP | V8: OSM
L9: < 1 HARI | M9: 1 - 3 HARI | N9: > 3 HARI | P9: KNDL PLGN | Q9: KNDL TEKNIS | R9: KNDL SYS | S9: OTHERS | Z9: KNDL PLGN | AA9: KNDL TEKNIS | AB9: KNDL SYS | AC9: OTHERS
B10: BALI | C10: 0 | D10: 19 | E10: 1 | F10: 2 | G10: 1 | H10: 0 | I10: 7 | J10: 0 | K10: 0 | L10: 2 | M10: 0 | N10: 0 | O10: 2 | P10: 0 | Q10: 0 | R10: 0 | S10: 0 | T10: 0 | U10: 0 | V10: 0 | W10: 0 | X10: 0 | Y10: 5 | Z10: 0 | AA10: 0 | AB10: 0 | AC10: 0 | AD10: 0 | AE10: 0 | AF10: 36.84 | AG10: 26.32 | AH10: 71.43
B11: JATIM BARAT | C11: 0 | D11: 30 | E11: 2 | F11: 2 | G11: 0 | H11: 0 | I11: 11 | J11: 1 | K11: 5 | L11: 1 | M11: 0 | N11: 0 | O11: 1 | P11: 0 | Q11: 0 | R11: 0 | S11: 0 | T11: 0 | U11: 0 | V11: 0 | W11: 0 | X11: 1 | Y11: 6 | Z11: 0 | AA11: 0 | AB11: 0 | AC11: 0 | AD11: 0 | AE11: 1 | AF11: 26.67 | AG11: 21.43 | AH11: 75.00
B12: JATIM TIMUR | C12: 0 | D12: 27 | E12: 2 | F12: 0 | G12: 1 | H12: 0 | I12: 9 | J12: 0 | K12: 1 | L12: 0 | M12: 0 | N12: 0 | O12: 0 | P12: 0 | Q12: 0 | R12: 0 | S12: 0 | T12: 0 | U12: 0 | V12: 0 | W12: 0 | X12: 0 | Y12: 7 | Z12: 0 | AA12: 0 | AB12: 0 | AC12: 0 | AD12: 0 | AE12: 0 | AF12: 25.93 | AG12: 25.93 | AH12: 100.00
B13: NUSA TENGGARA | C13: 0 | D13: 23 | E13: 0 | F13: 0 | G13: 1 | H13: 0 | I13: 16 | J13: 0 | K13: 0 | L13: 2 | M13: 0 | N13: 0 | O13: 2 | P13: 0 | Q13: 0 | R13: 0 | S13: 0 | T13: 0 | U13: 0 | V13: 0 | W13: 0 | X13: 1 | Y13: 2 | Z13: 0 | AA13: 0 | AB13: 0 | AC13: 0 | AD13: 0 | AE13: 0 | AF13: 21.74 | AG13: 8.70 | AH13: 40.00
B14: SEMARANG JATENG UTARA | C14: 0 | D14: 15 | E14: 4 | F14: 0 | G14: 0 | H14: 0 | I14: 9 | J14: 0 | K14: 0 | L14: 0 | M14: 0 | N14: 0 | O14: 0 | P14: 0 | Q14: 0 | R14: 0 | S14: 0 | T14: 0 | U14: 0 | V14: 0 | W14: 0 | X14: 0 | Y14: 2 | Z14: 0 | AA14: 0 | AB14: 0 | AC14: 0 | AD14: 0 | AE14: 0 | AF14: 13.33 | AG14: 13.33 | AH14: 100.00
B15: SOLO JATENG TIMUR | C15: 0 | D15: 15 | E15: 3 | F15: 3 | G15: 1 | H15: 0 | I15: 2 | J15: 0 | K15: 0 | L15: 3 | M15: 0 | N15: 0 | O15: 3 | P15: 0 | Q15: 0 | R15: 0 | S15: 0 | T15: 0 | U15: 0 | V15: 0 | W15: 0 | X15: 1 | Y15: 1 | Z15: 0 | AA15: 0 | AB15: 0 | AC15: 0 | AD15: 0 | AE15: 0 | AF15: 33.33 | AG15: 6.67 | AH15: 20.00
B16: SURAMADU | C16: 0 | D16: 31 | E16: 1 | F16: 0 | G16: 0 | H16: 0 | I16: 15 | J16: 1 | K16: 0 | L16: 2 | M16: 0 | N16: 0 | O16: 2 | P16: 0 | Q16: 0 | R16: 0 | S16: 1 | T16: 0 | U16: 0 | V16: 0 | W16: 1 | X16: 2 | Y16: 6 | Z16: 0 | AA16: 0 | AB16: 0 | AC16: 0 | AD16: 0 | AE16: 1 | AF16: 35.48 | AG16: 20.69 | AH16: 54.55
B17: YOGYA JATENG SELATAN | C17: 0 | D17: 27 | E17: 1 | F17: 2 | G17: 2 | H17: 0 | I17: 10 | J17: 0 | K17: 0 | L17: 2 | M17: 0 | N17: 0 | O17: 2 | P17: 0 | Q17: 0 | R17: 0 | S17: 0 | T17: 0 | U17: 0 | V17: 0 | W17: 0 | X17: 0 | Y17: 9 | Z17: 0 | AA17: 0 | AB17: 0 | AC17: 0 | AD17: 0 | AE17: 0 | AF17: 40.74 | AG17: 33.33 | AH17: 81.82
B18: TOTAL | C18: 0 | D18: 187 | E18: 14 | F18: 9 | G18: 6 | H18: 0 | I18: 79 | J18: 2 | K18: 6 | L18: 12 | M18: 0 | N18: 0 | O18: 12 | P18: 0 | Q18: 0 | R18: 0 | S18: 1 | T18: 0 | U18: 0 | V18: 0 | W18: 1 | X18: 5 | Y18: 38 | Z18: 0 | AA18: 0 | AB18: 0 | AC18: 0 | AD18: 0 | AE18: 2 | AF18: 29.95 | AG18: 20.77 | AH18: 67.86
B20: ="PROVISIONING INDIBIZ TR3 JBN HARIAN "&TEXT(TODAY(),"YYYY-MM-DD ")&TEXT(NOW(),"HH:MM")&" WIB" -> PROVISIONING INDIBIZ TR3 JBN HARIAN 2026-10-16 10:57 WIB
B21: Last update proses : 30-08-2024 15:48:52 WIB (Source: ETL XPRO)
B23: WITEL | C23: REGISTERED (RE) | D23: INPROGRESS SC+QC1+FCC | E23: CANCEL BY FCC | F23: SURVEY NEW MANJA | G23: UN-SC | H23: OGP | L23: TOTAL OGP | M23: JML COMP (PS) | N23: CANCEL | P23: TOTAL CANCEL | Q23: REVOKE
H24: PRE PI | I24: PI | J24: FALLOUT | K24: ACT COMP (QC2)
N26: KNDL PLGN | O26: KNDL NON PLGN
B27: BALI | C27: =D10 -> 19 | D27: =E10+F10+G10 -> 4 | E27: =H10 -> 0 | F27: =I10 -> 7 | G27: =J10 -> 0 | H27: =K10 -> 0 | I27: =O10 -> 2 | J27: =W10 -> 0 | K27: =X10 -> 0 | L27: =SUM(H27:K27) -> 2 | M27: =Y10 -> 5 | N27: =Z10 -> 0 | O27: =AD10-N27 -> 0 | P27: =SUM(N27:O27) -> 0 | Q27: =AE10 -> 0
B28: JATIM BARAT | C28: =D11 -> 30 | D28: =E11+F11+G11 -> 4 | E28: =H11 -> 0 | F28: =I11 -> 11 | G28: =J11 -> 1 | H28: =K11 -> 5 | I28: =O11 -> 1 | J28: =W11 -> 0 | K28: =X11 -> 1 | L28: =SUM(H28:K28) -> 7 | M28: =Y11 -> 6 | N28: =Z11 -> 0 | O28: =AD11-N28 -> 0 | P28: =SUM(N28:O28) -> 0 | Q28: =AE11 -> 1
B29: JATIM TIMUR | C29: =D12 -> 27 | D29: =E12+F12+G12 -> 3 | E29: =H12 -> 0 | F29: =I12 -> 9 | G29: =J12 -> 0 | H29: =K12 -> 1 | I29: =O12 -> 0 | J29: =W12 -> 0 | K29: =X12 -> 0 | L29: =SUM(H29:K29) -> 1 | M29: =Y12 -> 7 | N29: =Z12 -> 0 | O29: =AD12-N29 -> 0 | P29: =SUM(N29:O29) -> 0 | Q29: =AE12 -> 0
B30: NUSRA | C30: =D13 -> 23 | D30: =E13+F13+G13 -> 1 | E30: =H13 -> 0 | F30: =I13 -> 16 | G30: =J13 -> 0 | H30: =K13 -> 0 | I30: =O13 -> 2 | J30: =W13 -> 0 | K30: =X13 -> 1 | L30: =SUM(H30:K30) -> 3 | M30: =Y13 -> 2 | N30: =Z13 -> 0 | O30: =AD13-N30 -> 0 | P30: =SUM(N30:O30) -> 0 | Q30: =AE13 -> 0
B31: SURAMADU | C31: =D16 -> 31 | D31: =SUM(E16,F16,G16) -> 1 | E31: =H16 -> 0 | F31: =I16 -> 15 | G31: =J16 -> 1 | H31: =K16 -> 0 | I31: =O16 -> 2 | J31: =W16 -> 1 | K31: =X16 -> 2 | L31: =SUM(H31:K31) -> 5 | M31: =Y16 -> 6 | N31: =Z16 -> 0 | O31: =AD16-N31 -> 0 | P31: =SUM(N31:O31) -> 0 | Q31: =AE16 -> 1
B32: TOTAL | C32: =SUM(C27:C31) -> 130 | D32: =SUM(D27:D31) -> 13 | E32: =SUM(E27:E31) -> 0 | F32: =SUM(F27:F31) -> 58 | G32: =SUM(G27:G31) -> 2 | H32: =SUM(H27:H31) -> 6 | I32: =SUM(I27:I31) -> 7 | J32: =SUM(J27:J31) -> 1 | ... Q32: =SUM(Q27:Q31) -> 2
B34: Keterangan | C34: UIC
C35: Inputer, DIT, FCC
C36: Order Cancel & Revoke
C37: TA, BGESOPS, DAMAN, DIT
C38: Completed (PS)
B40: ="PROVISIONING INDIBIZ TR3 JBN BY TELDA MTD "&TEXT(TODAY(),"YYYY-MM-DD ")&TEXT(NOW(),"HH:MM")&" WIB" -> PROVISIONING INDIBIZ TR3 JBN BY TELDA MTD 2026-10-16 10:57 WIB
B41: Last update proses : 30-08-2024 13:48:46 WIB (Source: ETL XPRO)
B43: WITEL | C43: TELDA | D43: REGISTERED (RE) | E43: INPROGRESS SC+QC1+FCC | F43: CANCEL BY FCC | G43: SURVEY NEW MANJA | H43: UN-SC | I43: OGP | M43: TOTAL OGP | N43: JML COMP (PS) | O43: CANCEL | Q43: TOTAL CANCEL | R43: REVOKE
I44: PRE PI | J44: PI | K44: FALLOUT | L44: ACT COMP (QC2)
O46: KNDL PLGN | P46: KNDL NON PLGN
B47: BALI | C47: GIANYAR | D47: ='LOOKUP telda'!E7 -> 12 | E47: ='LOOKUP telda'!F7+'LOOKUP telda'!G7+'LOOKUP telda'!H7 -> 0 | F47: ='LOOKUP telda'!I7 -> 0 | G47: ='LOOKUP telda'!J7 -> 0 | H47: ='LOOKUP telda'!K7 -> 0 | I47: ='LOOKUP telda'!L7 -> 0 | J47: ='LOOKUP telda'!P7 -> 0 | K47: ='LOOKUP telda'!X7 -> 0 | L47: ='LOOKUP telda'!Y7 -> 0 | M47: =SUM('DATA MTD'!I47:L47) -> 0 | N47: ='LOOKUP telda'!Z7 -> 9 | O47: ='LOOKUP telda'!AA7 -> 0 | P47: ='LOOKUP telda'!AE7-'LOOKUP telda'!AA7 -> 0 | Q47: =SUM(O47:P47) -> 0 | R47: ='LOOKUP telda'!AF7 -> 3
C48: JEMBRANA | D48: ='LOOKUP telda'!E8 -> 1 | E48: ='LOOKUP telda'!F8+'LOOKUP telda'!G8+'LOOKUP telda'!H8 -> 0 | F48: ='LOOKUP telda'!I8 -> 0 | G48: ='LOOKUP telda'!J8 -> 0 | H48: ='LOOKUP telda'!K8 -> 0 | I48: ='LOOKUP telda'!L8 -> 0 | J48: ='LOOKUP telda'!P8 -> 0 | K48: ='LOOKUP telda'!X8 -> 0 | L48: ='LOOKUP telda'!Y8 -> 0 | M48: =SUM('DATA MTD'!I48:L48) -> 0 | N48: ='LOOKUP telda'!Z8 -> 1 | O48: ='LOOKUP telda'!AA8 -> 0 | P48: ='LOOKUP telda'!AE8-'LOOKUP telda'!AA8 -> 0 | Q48: =SUM(O48:P48) -> 0 | R48: ='LOOKUP telda'!AF8 -> 0
C49: JIMBARAN | D49: ='LOOKUP telda'!E9 -> 15 | E49: ='LOOKUP telda'!F9+'LOOKUP telda'!G9+'LOOKUP telda'!H9 -> 0 | F49: ='LOOKUP telda'!I9 -> 3 | G49: ='LOOKUP telda'!J9 -> 1 | H49: ='LOOKUP telda'!K9 -> 0 | I49: ='LOOKUP telda'!L9 -> 0 | J49: ='LOOKUP telda'!P9 -> 3 | K49: ='LOOKUP telda'!X9 -> 1 | L49: ='LOOKUP telda'!Y9 -> 0 | M49: =SUM('DATA MTD'!I49:L49) -> 4 | N49: ='LOOKUP telda'!Z9 -> 5 | O49: ='LOOKUP telda'!AA9 -> 0 | P49: ='LOOKUP telda'!AE9-'LOOKUP telda'!AA9 -> 0 | Q49: =SUM(O49:P49) -> 0 | R49: ='LOOKUP telda'!AF9 -> 2
C50: KLUNGKUNG | D50: ='LOOKUP telda'!E10 -> 11 | E50: ='LOOKUP telda'!F10+'LOOKUP telda'!G10+'LOOKUP telda'!H10 -> 0 | F50: ='LOOKUP telda'!I10 -> 1 | G50: ='LOOKUP telda'!J10 -> 2 | H50: ='LOOKUP telda'!K10 -> 0 | I50: ='LOOKUP telda'!L10 -> 0 | J50: ='LOOKUP telda'!P10 -> 1 | K50: ='LOOKUP telda'!X10 -> 0 | L50: ='LOOKUP telda'!Y10 -> 0 | M50: =SUM('DATA MTD'!I50:L50) -> 1 | N50: ='LOOKUP telda'!Z10 -> 6 | O50: ='LOOKUP telda'!AA10 -> 0 | P50: ='LOOKUP telda'!AE10-'LOOKUP telda'!AA10 -> 0 | Q50: =SUM(O50:P50) -> 0 | R50: ='LOOKUP telda'!AF10 -> 1
C51: SANUR | D51: ='LOOKUP telda'!E11 -> 14 | E51: ='LOOKUP telda'!F11+'LOOKUP telda'!G11+'LOOKUP telda'!H11 -> 0 | F51: ='LOOKUP telda'!I11 -> 1 | G51: ='LOOKUP telda'!J11 -> 1 | H51: ='LOOKUP telda'!K11 -> 0 | I51: ='LOOKUP telda'!L11 -> 0 | J51: ='LOOKUP telda'!P11 -> 0 | K51: ='LOOKUP telda'!X11 -> 0 | L51: ='LOOKUP telda'!Y11 -> 1 | M51: =SUM('DATA MTD'!I51:L51) -> 1 | N51: ='LOOKUP telda'!Z11 -> 10 | O51: ='LOOKUP telda'!AA11 -> 0 | P51: ='LOOKUP telda'!AE11-'LOOKUP telda'!AA11 -> 0 | Q51: =SUM(O51:P51) -> 0 | R51: ='LOOKUP telda'!AF11 -> 1
...

Sheet HARIAN
C2: ="PROVISIONING NEW SALES INDIBIZ TR3 JBN MTD "&TEXT(TODAY()-1,"YYYY-MM-DD ") -> PROVISIONING NEW SALES INDIBIZ TR3 JBN MTD 2026-10-15
C3: ="PERIODE ORDER & PS : 2026-01-01 to "&TEXT(TODAY()-1,"YYYY-MM-DD ") -> PERIODE ORDER & PS : 2026-01-01 to 2026-10-15
C4: Last update proses : 06-03-2026 15:19:48 WIB (Source: ETL XPRO)
C6: WITEL | D6: (RE) | E6: INPROGRESS SC+QC1+FCC | F6: CANCEL | I6: REVOKE | J6: SURVEY NEW MANJA | K6: UN-SC | L6: OGP | P6: JML COMP (PS) | Q6: PS/RE (%) (Target 80%) | R6: PS/PI (%) (Target 88%) | S6: TTI COMPLY 1X 24 (%) (Target 85%)
F9: BY FCC | G9: KNDL PLGN | H9: KNDL NON PLGN | L9: PRE PI | M9: PI | N9: FALLOUT | O9: ACT COMP (QC2) | X9: =205/216 -> 0.94907407
C10: BALI | D10: ='COPY DATA XPRO'!E63 -> 126 | E10: ='COPY DATA XPRO'!F63+'COPY DATA XPRO'!G63+'COPY DATA XPRO'!H63 -> 1 | F10: ='COPY DATA XPRO'!I63 -> 7 | G10: ='COPY DATA XPRO'!AA63 -> 1 | H10: ='COPY DATA XPRO'!AE63-HARIAN!G10 -> 11 | I10: ='COPY DATA XPRO'!AF63 -> 14 | J10: ='COPY DATA XPRO'!J63 -> 5 | K10: ='COPY DATA XPRO'!K63 -> 10 | L10: ='COPY DATA XPRO'!L63 -> 0 | M10: ='COPY DATA XPRO'!P63 -> 12 | N10: ='COPY DATA XPRO'!X63 -> 4 | O10: ='COPY DATA XPRO'!Y63 -> 1 | P10: ='COPY DATA XPRO'!Z63 -> 60 | Q10: =T10 -> 0.63157895 | R10: =U10 -> 0.77922078 | S10: =VLOOKUP(C10,Sheet3!$A$19:$G$81,7,FALSE) -> 0.91666667 | T10: =P10/(D10-F10-K10-I10) -> 0.63157895 | U10: =P10/(M10+N10+O10+P10) -> 0.77922078
C11: JATIM BARAT | D11: ='COPY DATA XPRO'!E64 -> 231 | E11: ='COPY DATA XPRO'!F64+'COPY DATA XPRO'!G64+'COPY DATA XPRO'!H64 -> 5 | F11: ='COPY DATA XPRO'!I64 -> 5 | G11: ='COPY DATA XPRO'!AA64 -> 3 | H11: ='COPY DATA XPRO'!AE64-HARIAN!G11 -> 8 | I11: ='COPY DATA XPRO'!AF64 -> 13 | J11: ='COPY DATA XPRO'!J64 -> 14 | K11: ='COPY DATA XPRO'!K64 -> 8 | L11: ='COPY DATA XPRO'!L64 -> 0 | M11: ='COPY DATA XPRO'!P64 -> 1 | N11: ='COPY DATA XPRO'!X64 -> 1 | O11: ='COPY DATA XPRO'!Y64 -> 3 | P11: ='COPY DATA XPRO'!Z64 -> 169 | Q11: =T11 -> 0.82439024 | R11: =U11 -> 0.97126437 | S11: =VLOOKUP(C11,Sheet3!$A$19:$G$81,7,FALSE) -> 0.98224852 | T11: =P11/(D11-F11-K11-I11) -> 0.82439024 | U11: =P11/(M11+N11+O11+P11) -> 0.97126437
C12: JATIM TIMUR | D12: ='COPY DATA XPRO'!E65 -> 173 | E12: ='COPY DATA XPRO'!F65+'COPY DATA XPRO'!G65+'COPY DATA XPRO'!H65 -> 4 | F12: ='COPY DATA XPRO'!I65 -> 2 | G12: ='COPY DATA XPRO'!AA65 -> 5 | H12: ='COPY DATA XPRO'!AE65-HARIAN!G12 -> 8 | I12: ='COPY DATA XPRO'!AF65 -> 9 | J12: ='COPY DATA XPRO'!J65 -> 5 | K12: ='COPY DATA XPRO'!K65 -> 2 | L12: ='COPY DATA XPRO'!L65 -> 0 | M12: ='COPY DATA XPRO'!P65 -> 1 | N12: ='COPY DATA XPRO'!X65 -> 2 | O12: ='COPY DATA XPRO'!Y65 -> 5 | P12: ='COPY DATA XPRO'!Z65 -> 130 | Q12: =T12 -> 0.8125 | R12: =U12 -> 0.94202899 | S12: =VLOOKUP(C12,Sheet3!$A$19:$G$81,7,FALSE) -> 1 | T12: =P12/(D12-F12-K12-I12) -> 0.8125 | U12: =P12/(M12+N12+O12+P12) -> 0.94202899
C13: NUSA TENGGARA | D13: ='COPY DATA XPRO'!E66 -> 210 | E13: ='COPY DATA XPRO'!F66+'COPY DATA XPRO'!G66+'COPY DATA XPRO'!H66 -> 6 | F13: ='COPY DATA XPRO'!I66 -> 4 | G13: ='COPY DATA XPRO'!AA66 -> 2 | H13: ='COPY DATA XPRO'!AE66-HARIAN!G13 -> 3 | I13: ='COPY DATA XPRO'!AF66 -> 31 | J13: ='COPY DATA XPRO'!J66 -> 9 | K13: ='COPY DATA XPRO'!K66 -> 5 | L13: ='COPY DATA XPRO'!L66 -> 1 | M13: ='COPY DATA XPRO'!P66 -> 19 | N13: ='COPY DATA XPRO'!X66 -> 5 | O13: ='COPY DATA XPRO'!Y66 -> 5 | P13: ='COPY DATA XPRO'!Z66 -> 121 | Q13: =T13 -> 0.71176471 | R13: =U13 -> 0.80666667 | S13: =VLOOKUP(C13,Sheet3!$A$19:$G$81,7,FALSE) -> 0.76033058 | T13: =P13/(D13-F13-K13-I13) -> 0.71176471 | U13: =P13/(M13+N13+O13+P13) -> 0.80666667
C14: SURAMADU | D14: ='COPY DATA XPRO'!E69 -> 274 | E14: ='COPY DATA XPRO'!F69+'COPY DATA XPRO'!G69+'COPY DATA XPRO'!H69 -> 11 | F14: ='COPY DATA XPRO'!I69 -> 6 | G14: ='COPY DATA XPRO'!AA69 -> 1 | H14: ='COPY DATA XPRO'!AE69-HARIAN!G14 -> 3 | I14: ='COPY DATA XPRO'!AF69 -> 47 | J14: ='COPY DATA XPRO'!J69 -> 29 | K14: ='COPY DATA XPRO'!K69 -> 2 | L14: ='COPY DATA XPRO'!L69 -> 1 | M14: ='COPY DATA XPRO'!P69 -> 1 | N14: ='COPY DATA XPRO'!X69 -> 5 | O14: ='COPY DATA XPRO'!Y69 -> 4 | P14: ='COPY DATA XPRO'!Z69 -> 164 | Q14: =T14 -> 0.74885845 | R14: =U14 -> 0.94252874 | S14: =VLOOKUP(C14,Sheet3!$A$19:$G$81,7,FALSE) -> 0.98170732 | T14: =P14/(D14-F14-K14-I14) -> 0.74885845 | U14: =P14/(M14+N14+O14+P14) -> 0.94252874
C15: TOTAL | D15: =SUM(D10:D14) -> 1014 | E15: =SUM(E10:E14) -> 27 | F15: =SUM(F10:F14) -> 24 | G15: =SUM(G10:G14) -> 12 | H15: =SUM(H10:H14) -> 33 | I15: =SUM(I10:I14) -> 114 | J15: =SUM(J10:J14) -> 62 | K15: =SUM(K10:K14) -> 27 | ... P15: =SUM(P10:P14) -> 644 | Q15: =T15 -> 0.75853946 | R15: =U15 -> 0.90322581 | S15: =Sheet3!G10 -> 0.9378882 | T15: =P15/(D15-F15-K15-I15) -> 0.75853946 | U15: =P15/(M15+N15+O15+P15) -> 0.90322581
C17: Keterangan | D17: UIC | G17: * Target PS/PI Sesuai dengan Draft SLA MSA 2025 | L17: FORMULA
D18: Inputer, DIT, FCC | G18: 1. Time To Install (TTI) Comply Indibiz | 1x24 jam | L18: PI/RE : (Total PI + Total Fallout + Act Comp + Jumlah PS + Total Cancel) / Registered
D19: Order Cancel & Revoke | G19: 2. Fulfillment Guarantee (FFG) Indibiz | 60 hari | L19: PS/RE : PS / (Registered - Cancel by FCC - UNSC - Revoke)
D20: TA, BGESOPS, DAMAN, DIT | G20: 3. TTR Fulfillment Guarantee Indibiz | 3 jam | L20: PS/PI : PS / (Total PI + Total Fallout + Act Comp + Jumlah PS)
D21: Completed (PS) | G21: 4. PS to PI Ratio Indibiz Q3 88 % (Incremental)
D22: Performansi | G22: 5. Underspec warranty Indibiz | <= -25dBm
B24: =C2 -> PROVISIONING NEW SALES INDIBIZ TR3 JBN MTD 2026-10-15
B25: =C3 -> PERIODE ORDER & PS : 2026-01-01 to 2026-10-15
B26: =C4 -> Last update proses : 06-03-2026 15:19:48 WIB (Source: ETL XPRO)
B29: WITEL | C29: TELDA | D29: (RE) | E29: INPROGRESS SC+QC1+FCC | F29: CANCEL | I29: REVOKE | J29: SURVEY NEW MANJA | K29: UN-SC | L29: OGP | P29: JML COMP (PS) | Q29: PS/RE (%) (Target 80%) | R29: PS/PI (%) (Target 88%) | S29: TTI COMPLY 1X 24 (%) (Target 85%)
F32: BY FCC | G32: KNDL PLGN | H32: KNDL NON PLGN | L32: PRE PI | M32: PI | N32: FALLOUT | O32: ACT COMP (QC2) | V32: new telda
B33: BALI | C33: GIANYAR | D33: ='LOOKUP telda'!E7 -> 12 | E33: ='LOOKUP telda'!F7+'LOOKUP telda'!G7+'LOOKUP telda'!H7 -> 0 | F33: ='LOOKUP telda'!I7 -> 0 | G33: ='LOOKUP telda'!AA7 -> 0 | H33: ='LOOKUP telda'!AE7-'LOOKUP telda'!AA7 -> 0 | I33: ='LOOKUP telda'!AF7 -> 3 | J33: ='LOOKUP telda'!J7 -> 0 | K33: ='LOOKUP telda'!K7 -> 0 | L33: ='LOOKUP telda'!L7 -> 0 | M33: ='LOOKUP telda'!P7 -> 0 | N33: ='LOOKUP telda'!X7 -> 0 | O33: ='LOOKUP telda'!Y7 -> 0 | P33: ='LOOKUP telda'!Z7 -> 9 | Q33: =T33 -> 1 | R33: =U33 -> 1 | S33: =VLOOKUP(C33,Sheet3!$A$19:$G$81,7,FALSE) -> 0.66666667 | T33: =IFERROR(P33/(D33-F33-K33-I33),0) -> 1 | U33: =IFERROR(P33/(M33+N33+O33+P33),0) -> 1 | V33: =VLOOKUP(C33,Sheet5!$A$2:$J$270,8,FALSE) -> GIANYAR
C34: JEMBRANA | D34: ='LOOKUP telda'!E8 -> 1 | E34: ='LOOKUP telda'!F8+'LOOKUP telda'!G8+'LOOKUP telda'!H8 -> 0 | F34: ='LOOKUP telda'!I8 -> 0 | G34: ='LOOKUP telda'!AA8 -> 0 | H34: ='LOOKUP telda'!AE8-'LOOKUP telda'!AA8 -> 0 | I34: ='LOOKUP telda'!AF8 -> 0 | J34: ='LOOKUP telda'!J8 -> 0 | K34: ='LOOKUP telda'!K8 -> 0 | L34: ='LOOKUP telda'!L8 -> 0 | M34: ='LOOKUP telda'!P8 -> 0 | N34: ='LOOKUP telda'!X8 -> 0 | O34: ='LOOKUP telda'!Y8 -> 0 | P34: ='LOOKUP telda'!Z8 -> 1 | Q34: =T34 -> 1 | R34: =U34 -> 1 | S34: =VLOOKUP(C34,Sheet3!$A$19:$G$81,7,FALSE) -> 1 | T34: =IFERROR(P34/(D34-F34-K34-I34),0) -> 1 | U34: =IFERROR(P34/(M34+N34+O34+P34),0) -> 1 | V34: =VLOOKUP(C34,Sheet5!$A$2:$J$270,8,FALSE) -> TABANAN
C35: JIMBARAN | D35: ='LOOKUP telda'!E9 -> 15 | E35: ='LOOKUP telda'!F9+'LOOKUP telda'!G9+'LOOKUP telda'!H9 -> 0 | F35: ='LOOKUP telda'!I9 -> 3 | G35: ='LOOKUP telda'!AA9 -> 0 | H35: ='LOOKUP telda'!AE9-'LOOKUP telda'!AA9 -> 0 | I35: ='LOOKUP telda'!AF9 -> 2 | J35: ='LOOKUP telda'!J9 -> 1 | K35: ='LOOKUP telda'!K9 -> 0 | L35: ='LOOKUP telda'!L9 -> 0 | M35: ='LOOKUP telda'!P9 -> 3 | N35: ='LOOKUP telda'!X9 -> 1 | O35: ='LOOKUP telda'!Y9 -> 0 | P35: ='LOOKUP telda'!Z9 -> 5 | Q35: =T35 -> 0.5 | R35: =U35 -> 0.55555556 | S35: =VLOOKUP(C35,Sheet3!$A$19:$G$81,7,FALSE) -> 0.8 | T35: =IFERROR(P35/(D35-F35-K35-I35),0) -> 0.5 | U35: =IFERROR(P35/(M35+N35+O35+P35),0) -> 0.55555556 | V35: =VLOOKUP(C35,Sheet5!$A$2:$J$270,8,FALSE) -> JIMBARAN
C36: KLUNGKUNG | D36: ='LOOKUP telda'!E10 -> 11 | E36: ='LOOKUP telda'!F10+'LOOKUP telda'!G10+'LOOKUP telda'!H10 -> 0 | F36: ='LOOKUP telda'!I10 -> 1 | G36: ='LOOKUP telda'!AA10 -> 0 | H36: ='LOOKUP telda'!AE10-'LOOKUP telda'!AA10 -> 0 | I36: ='LOOKUP telda'!AF10 -> 1 | J36: ='LOOKUP telda'!J10 -> 2 | K36: ='LOOKUP telda'!K10 -> 0 | L36: ='LOOKUP telda'!L10 -> 0 | M36: ='LOOKUP telda'!P10 -> 1 | N36: ='LOOKUP telda'!X10 -> 0 | O36: ='LOOKUP telda'!Y10 -> 0 | P36: ='LOOKUP telda'!Z10 -> 6 | Q36: =T36 -> 0.66666667 | R36: =U36 -> 0.85714286 | S36: =VLOOKUP(C36,Sheet3!$A$19:$G$81,7,FALSE) -> 1 | T36: =IFERROR(P36/(D36-F36-K36-I36),0) -> 0.66666667 | U36: =IFERROR(P36/(M36+N36+O36+P36),0) -> 0.85714286 | V36: =VLOOKUP(C36,Sheet5!$A$2:$J$270,8,FALSE) -> KLUNGKUNG
C37: SANUR | D37: ='LOOKUP telda'!E11 -> 14 | E37: ='LOOKUP telda'!F11+'LOOKUP telda'!G11+'LOOKUP telda'!H11 -> 0 | F37: ='LOOKUP telda'!I11 -> 1 | G37: ='LOOKUP telda'!AA11 -> 0 | H37: ='LOOKUP telda'!AE11-'LOOKUP telda'!AA11 -> 0 | I37: ='LOOKUP telda'!AF11 -> 1 | J37: ='LOOKUP telda'!J11 -> 1 | K37: ='LOOKUP telda'!K11 -> 0 | L37: ='LOOKUP telda'!L11 -> 0 | M37: ='LOOKUP telda'!P11 -> 0 | N37: ='LOOKUP telda'!X11 -> 0 | O37: ='LOOKUP telda'!Y11 -> 1 | P37: ='LOOKUP telda'!Z11 -> 10 | Q37: =T37 -> 0.83333333 | R37: =U37 -> 0.90909091 | S37: =VLOOKUP(C37,Sheet3!$A$19:$G$81,7,FALSE) -> 1 | T37: =IFERROR(P37/(D37-F37-K37-I37),0) -> 0.83333333 | U37: =IFERROR(P37/(M37+N37+O37+P37),0) -> 0.90909091 | V37: =VLOOKUP(C37,Sheet5!$A$2:$J$270,8,FALSE) -> SANUR
C38: SINGARAJA | D38: ='LOOKUP telda'!E12 -> 7 | E38: ='LOOKUP telda'!F12+'LOOKUP telda'!G12+'LOOKUP telda'!H12 -> 0 | F38: ='LOOKUP telda'!I12 -> 0 | G38: ='LOOKUP telda'!AA12 -> 0 | H38: ='LOOKUP telda'!AE12-'LOOKUP telda'!AA12 -> 0 | I38: ='LOOKUP telda'!AF12 -> 1 | J38: ='LOOKUP telda'!J12 -> 0 | K38: ='LOOKUP telda'!K12 -> 0 | L38: ='LOOKUP telda'!L12 -> 0 | M38: ='LOOKUP telda'!P12 -> 1 | N38: ='LOOKUP telda'!X12 -> 0 | O38: ='LOOKUP telda'!Y12 -> 0 | P38: ='LOOKUP telda'!Z12 -> 5 | Q38: =T38 -> 0.83333333 | R38: =U38 -> 0.83333333 | S38: =VLOOKUP(C38,Sheet3!$A$19:$G$81,7,FALSE) -> 1 | T38: =IFERROR(P38/(D38-F38-K38-I38),0) -> 0.83333333 | U38: =IFERROR(P38/(M38+N38+O38+P38),0) -> 0.83333333 | V38: =VLOOKUP(C38,Sheet5!$A$2:$J$270,8,FALSE) -> SINGARAJA
C39: TABANAN | D39: ='LOOKUP telda'!E13 -> 48 | E39: ='LOOKUP telda'!F13+'LOOKUP telda'!G13+'LOOKUP telda'!H13 -> 1 | F39: ='LOOKUP telda'!I13 -> 2 | G39: ='LOOKUP telda'!AA13 -> 0 | H39: ='LOOKUP telda'!AE13-'LOOKUP telda'!AA13 -> 11 | I39: ='LOOKUP telda'!AF13 -> 3 | J39: ='LOOKUP telda'!J13 -> 1 | K39: ='LOOKUP telda'!K13 -> 10 | L39: ='LOOKUP telda'!L13 -> 0 | M39: ='LOOKUP telda'!P13 -> 3 | N39: ='LOOKUP telda'!X13 -> 2 | O39: ='LOOKUP telda'!Y13 -> 0 | P39: ='LOOKUP telda'!Z13 -> 15 | Q39: =T39 -> 0.45454545 | R39: =U39 -> 0.75 | S39: =VLOOKUP(C39,Sheet3!$A$19:$G$81,7,FALSE) -> 0.93333333 | T39: =IFERROR(P39/(D39-F39-K39-I39),0) -> 0.45454545 | U39: =IFERROR(P39/(M39+N39+O39+P39),0) -> 0.75 | V39: =VLOOKUP(C39,Sheet5!$A$2:$J$270,8,FALSE) -> TABANAN
C40: UBUNG | D40: ='LOOKUP telda'!E14 -> 18 | E40: ='LOOKUP telda'!F14+'LOOKUP telda'!G14+'LOOKUP telda'!H14 -> 0 | F40: ='LOOKUP telda'!I14 -> 0 | G40: ='LOOKUP telda'!AA14 -> 1 | H40: ='LOOKUP telda'!AE14-'LOOKUP telda'!AA14 -> 0 | I40: ='LOOKUP telda'!AF14 -> 3 | J40: ='LOOKUP telda'!J14 -> 0 | K40: ='LOOKUP telda'!K14 -> 0 | L40: ='LOOKUP telda'!L14 -> 0 | M40: ='LOOKUP telda'!P14 -> 4 | N40: ='LOOKUP telda'!X14 -> 1 | O40: ='LOOKUP telda'!Y14 -> 0 | P40: ='LOOKUP telda'!Z14 -> 9 | Q40: =T40 -> 0.6 | R40: =U40 -> 0.64285714 | S40: =VLOOKUP(C40,Sheet3!$A$19:$G$81,7,FALSE) -> 1 | T40: =IFERROR(P40/(D40-F40-K40-I40),0) -> 0.6 | U40: =IFERROR(P40/(M40+N40+O40+P40),0) -> 0.64285714 | V40: =VLOOKUP(C40,Sheet5!$A$2:$J$270,8,FALSE) -> UBUNG
B41: JATIM BARAT | C41: BATU | D41: ='LOOKUP telda'!E15 -> 31 | E41: ='LOOKUP telda'!F15+'LOOKUP telda'!G15+'LOOKUP telda'!H15 -> 3 | F41: ='LOOKUP telda'!I15 -> 0 | G41: ='LOOKUP telda'!AA15 -> 0 | H41: ='LOOKUP telda'!AE15-'LOOKUP telda'!AA15 -> 3 | I41: ='LOOKUP telda'!AF15 -> 1 | J41: ='LOOKUP telda'!J15 -> 8 | K41: ='LOOKUP telda'!K15 -> 0 | L41: ='LOOKUP telda'!L15 -> 0 | M41: ='LOOKUP telda'!P15 -> 0 | N41: ='LOOKUP telda'!X15 -> 0 | O41: ='LOOKUP telda'!Y15 -> 0 | P41: ='LOOKUP telda'!Z15 -> 16 | Q41: =T41 -> 0.53333333 | R41: =U41 -> 1 | S41: =VLOOKUP(C41,Sheet3!$A$19:$G$81,7,FALSE) -> 1 | T41: =IFERROR(P41/(D41-F41-K41-I41),0) -> 0.53333333 | U41: =IFERROR(P41/(M41+N41+O41+P41),0) -> 1 | V41: =VLOOKUP(C41,Sheet5!$A$2:$J$270,8,FALSE) -> BATU
C42: BLITAR | D42: ='LOOKUP telda'!E16 -> 12 | E42: ='LOOKUP telda'!F16+'LOOKUP telda'!G16+'LOOKUP telda'!H16 -> 0 | F42: ='LOOKUP telda'!I16 -> 0 | G42: ='LOOKUP telda'!AA16 -> 0 | H42: ='LOOKUP telda'!AE16-'LOOKUP telda'!AA16 -> 0 | I42: ='LOOKUP telda'!AF16 -> 0 | J42: ='LOOKUP telda'!J16 -> 0 | K42: ='LOOKUP telda'!K16 -> 0 | L42: ='LOOKUP telda'!L16 -> 0 | M42: ='LOOKUP telda'!P16 -> 0 | N42: ='LOOKUP telda'!X16 -> 0 | O42: ='LOOKUP telda'!Y16 -> 0 | P42: ='LOOKUP telda'!Z16 -> 12 | Q42: =T42 -> 1 | R42: =U42 -> 1 | S42: =VLOOKUP(C42,Sheet3!$A$19:$G$81,7,FALSE) -> 1 | T42: =IFERROR(P42/(D42-F42-K42-I42),0) -> 1 | U42: =IFERROR(P42/(M42+N42+O42+P42),0) -> 1 | V42: =VLOOKUP(C42,Sheet5!$A$2:$J$270,8,FALSE) -> BLITAR
C43: BOJONEGORO | D43: ='LOOKUP telda'!E17 -> 21 | E43: ='LOOKUP telda'!F17+'LOOKUP telda'!G17+'LOOKUP telda'!H17 -> 0 | F43: ='LOOKUP telda'!I17 -> 1 | G43: ='LOOKUP telda'!AA17 -> 0 | H43: ='LOOKUP telda'!AE17-'LOOKUP telda'!AA17 -> 0 | I43: ='LOOKUP telda'!AF17 -> 3 | J43: ='LOOKUP telda'!J17 -> 0 | K43: ='LOOKUP telda'!K17 -> 0 | L43: ='LOOKUP telda'!L17 -> 0 | M43: ='LOOKUP telda'!P17 -> 0 | N43: ='LOOKUP telda'!X17 -> 0 | O43: ='LOOKUP telda'!Y17 -> 1 | P43: ='LOOKUP telda'!Z17 -> 16 | Q43: =T43 -> 0.94117647 | R43: =U43 -> 0.94117647 | S43: =VLOOKUP(C43,Sheet3!$A$19:$G$81,7,FALSE) -> 1 | T43: =IFERROR(P43/(D43-F43-K43-I43),0) -> 0.94117647 | U43: =IFERROR(P43/(M43+N43+O43+P43),0) -> 0.94117647 | V43: =VLOOKUP(C43,Sheet5!$A$2:$J$270,8,FALSE) -> BOJONEGORO
C44: KEDIRI | D44: ='LOOKUP telda'!E18 -> 33 | E44: ='LOOKUP telda'!F18+'LOOKUP telda'!G18+'LOOKUP telda'!H18 -> 1 | F44: ='LOOKUP telda'!I18 -> 0 | G44: ='LOOKUP telda'!AA18 -> 0 | H44: ='LOOKUP telda'!AE18-'LOOKUP telda'!AA18 -> 1 | I44: ='LOOKUP telda'!AF18 -> 0 | J44: ='LOOKUP telda'!J18 -> 0 | K44: ='LOOKUP telda'!K18 -> 0 | L44: ='LOOKUP telda'!L18 -> 0 | M44: ='LOOKUP telda'!P18 -> 0 | N44: ='LOOKUP telda'!X18 -> 0 | O44: ='LOOKUP telda'!Y18 -> 1 | P44: ='LOOKUP telda'!Z18 -> 30 | Q44: =T44 -> 0.90909091 | R44: =U44 -> 0.96774194 | S44: =VLOOKUP(C44,Sheet3!$A$19:$G$81,7,FALSE) -> 0.93333333 | T44: =IFERROR(P44/(D44-F44-K44-I44),0) -> 0.90909091 | U44: =IFERROR(P44/(M44+N44+O44+P44),0) -> 0.96774194 | V44: =VLOOKUP(C44,Sheet5!$A$2:$J$270,8,FALSE) -> KEDIRI
C45: KEPANJEN | D45: ='LOOKUP telda'!E19 -> 34 | E45: ='LOOKUP telda'!F19+'LOOKUP telda'!G19+'LOOKUP telda'!H19 -> 0 | F45: ='LOOKUP telda'!I19 -> 0 | G45: ='LOOKUP telda'!AA19 -> 0 | H45: ='LOOKUP telda'!AE19-'LOOKUP telda'!AA19 -> 0 | I45: ='LOOKUP telda'!AF19 -> 3 | J45: ='LOOKUP telda'!J19 -> 0 | K45: ='LOOKUP telda'!K19 -> 0 | L45: ='LOOKUP telda'!L19 -> 0 | M45: ='LOOKUP telda'!P19 -> 0 | N45: ='LOOKUP telda'!X19 -> 0 | O45: ='LOOKUP telda'!Y19 -> 0 | P45: ='LOOKUP telda'!Z19 -> 31 | Q45: =T45 -> 1 | R45: =U45 -> 1 | S45: =VLOOKUP(C45,Sheet3!$A$19:$G$81,7,FALSE) -> #N/A | T45: =IFERROR(P45/(D45-F45-K45-I45),0) -> 1 | U45: =IFERROR(P45/(M45+N45+O45+P45),0) -> 1 | V45: =VLOOKUP(C45,Sheet5!$A$2:$J$270,8,FALSE) -> MALANG
C46: MADIUN | D46: ='LOOKUP telda'!E20 -> 8 | E46: ='LOOKUP telda'!F20+'LOOKUP telda'!G20+'LOOKUP telda'!H20 -> 0 | F46: ='LOOKUP telda'!I20 -> 0 | G46: ='LOOKUP telda'!AA20 -> 0 | H46: ='LOOKUP telda'!AE20-'LOOKUP telda'!AA20 -> 0 | I46: ='LOOKUP telda'!AF20 -> 0 | J46: ='LOOKUP telda'!J20 -> 0 | K46: ='LOOKUP telda'!K20 -> 0 | L46: ='LOOKUP telda'!L20 -> 0 | M46: ='LOOKUP telda'!P20 -> 0 | N46: ='LOOKUP telda'!X20 -> 0 | O46: ='LOOKUP telda'!Y20 -> 0 | P46: ='LOOKUP telda'!Z20 -> 7 | Q46: =T46 -> 0.875 | R46: =U46 -> 1 | S46: =VLOOKUP(C46,Sheet3!$A$19:$G$81,7,FALSE) -> 1 | T46: =IFERROR(P46/(D46-F46-K46-I46),0) -> 0.875 | U46: =IFERROR(P46/(M46+N46+O46+P46),0) -> 1 | V46: =VLOOKUP(C46,Sheet5!$A$2:$J$270,8,FALSE) -> MADIUN
C47: NGANJUK | D47: ='LOOKUP telda'!E21 -> 20 | E47: ='LOOKUP telda'!F21+'LOOKUP telda'!G21+'LOOKUP telda'!H21 -> 0 | F47: ='LOOKUP telda'!I21 -> 0 | G47: ='LOOKUP telda'!AA21 -> 0 | H47: ='LOOKUP telda'!AE21-'LOOKUP telda'!AA21 -> 1 | I47: ='LOOKUP telda'!AF21 -> 2 | J47: ='LOOKUP telda'!J21 -> 1 | K47: ='LOOKUP telda'!K21 -> 5 | L47: ='LOOKUP telda'!L21 -> 0 | M47: ='LOOKUP telda'!P21 -> 1 | N47: ='LOOKUP telda'!X21 -> 0 | O47: ='LOOKUP telda'!Y21 -> 1 | P47: ='LOOKUP telda'!Z21 -> 9 | Q47: =T47 -> 0.69230769 | R47: =U47 -> 0.81818182 | S47: =VLOOKUP(C47,Sheet3!$A$19:$G$81,7,FALSE) -> 1 | T47: =IFERROR(P47/(D47-F47-K47-I47),0) -> 0.69230769 | U47: =IFERROR(P47/(M47+N47+O47+P47),0) -> 0.81818182 | V47: =VLOOKUP(C47,Sheet5!$A$2:$J$270,8,FALSE) -> NGANJUK
C48: NGAWI | D48: ='LOOKUP telda'!E22 -> 8 | E48: ='LOOKUP telda'!F22+'LOOKUP telda'!G22+'LOOKUP telda'!H22 -> 0 | F48: ='LOOKUP telda'!I22 -> 0 | G48: ='LOOKUP telda'!AA22 -> 0 | H48: ='LOOKUP telda'!AE22-'LOOKUP telda'!AA22 -> 0 | I48: ='LOOKUP telda'!AF22 -> 0 | J48: ='LOOKUP telda'!J22 -> 1 | K48: ='LOOKUP telda'!K22 -> 0 | L48: ='LOOKUP telda'!L22 -> 0 | M48: ='LOOKUP telda'!P22 -> 0 | N48: ='LOOKUP telda'!X22 -> 1 | O48: ='LOOKUP telda'!Y22 -> 0 | P48: ='LOOKUP telda'!Z22 -> 6 | Q48: =T48 -> 0.75 | R48: =U48 -> 0.85714286 | S48: =VLOOKUP(C48,Sheet3!$A$19:$G$81,7,FALSE) -> #N/A | T48: =IFERROR(P48/(D48-F48-K48-I48),0) -> 0.75 | U48: =IFERROR(P48/(M48+N48+O48+P48),0) -> 0.85714286 | V48: =VLOOKUP(C48,Sheet5!$A$2:$J$270,8,FALSE) -> MADIUN
C49: PONOROGO | D49: ='LOOKUP telda'!E23 -> 21 | E49: ='LOOKUP telda'!F23+'LOOKUP telda'!G23+'LOOKUP telda'!H23 -> 0 | F49: ='LOOKUP telda'!I23 -> 0 | G49: ='LOOKUP telda'!AA23 -> 0 | H49: ='LOOKUP telda'!AE23-'LOOKUP telda'!AA23 -> 1 | I49: ='LOOKUP telda'!AF23 -> 2 | J49: ='LOOKUP telda'!J23 -> 2 | K49: ='LOOKUP telda'!K23 -> 1 | L49: ='LOOKUP telda'!L23 -> 0 | M49: ='LOOKUP telda'!P23 -> 0 | N49: ='LOOKUP telda'!X23 -> 0 | O49: ='LOOKUP telda'!Y23 -> 0 | P49: ='LOOKUP telda'!Z23 -> 15 | Q49: =T49 -> 0.83333333 | R49: =U49 -> 1 | S49: =VLOOKUP(C49,Sheet3!$A$19:$G$81,7,FALSE) -> 0.95238095 | T49: =IFERROR(P49/(D49-F49-K49-I49),0) -> 0.83333333 | U49: =IFERROR(P49/(M49+N49+O49+P49),0) -> 1 | V49: =VLOOKUP(C49,Sheet5!$A$2:$J$270,8,FALSE) -> PONOROGO
C50: TRENGGALEK | D50: ='LOOKUP telda'!E24 -> 8 | E50: ='LOOKUP telda'!F24+'LOOKUP telda'!G24+'LOOKUP telda'!H24 -> 0 | F50: ='LOOKUP telda'!I24 -> 0 | G50: ='LOOKUP telda'!AA24 -> 2 | H50: ='LOOKUP telda'!AE24-'LOOKUP telda'!AA24 -> 0 | I50: ='LOOKUP telda'!AF24 -> 0 | J50: ='LOOKUP telda'!J24 -> 0 | K50: ='LOOKUP telda'!K24 -> 0 | L50: ='LOOKUP telda'!L24 -> 0 | M50: ='LOOKUP telda'!P24 -> 0 | N50: ='LOOKUP telda'!X24 -> 0 | O50: ='LOOKUP telda'!Y24 -> 0 | P50: ='LOOKUP telda'!Z24 -> 6 | Q50: =T50 -> 0.75 | R50: =U50 -> 1 | S50: =VLOOKUP(C50,Sheet3!$A$19:$G$81,7,FALSE) -> #N/A | T50: =IFERROR(P50/(D50-F50-K50-I50),0) -> 0.75 | U50: =IFERROR(P50/(M50+N50+O50+P50),0) -> 1 | V50: =VLOOKUP(C50,Sheet5!$A$2:$J$270,8,FALSE) -> PONOROGO
...

Sheet Sheet1
A1: =LAPORAN!C1 -> PROVISIONING NEW SALES INDIBIZ TR3 JBN MTD H-1 2026-10-15
A2: =LAPORAN!C2 -> PERIODE ORDER & PS : 2026-10-01 to 2026-10-15
A3: =LAPORAN!C3 -> Last update proses : 16-10-2026 08:34:07 WIB (Source: ETL XPRO)
A5: WITEL | B5: (RE) | C5: REVOKE | D5: JML COMP (PS) | E5: REVOKE % | F5: PS/RE (%) (Target 80%) | G5: PS/PI (%) (Target 88%) | H5: TTI COMPLY 1X 24 (%) (Target 85%)
A6: =HARIAN!C10 -> BALI | B6: =HARIAN!D10 -> 126 | C6: =HARIAN!I10 -> 14 | D6: =HARIAN!P10 -> 60 | E6: =C6/B6 -> 0.11111111 | F6: =HARIAN!Q10 -> 0.63157895 | G6: =HARIAN!R10 -> 0.77922078 | H6: =HARIAN!S10 -> 0.91666667
A7: =HARIAN!C11 -> JATIM BARAT | B7: =HARIAN!D11 -> 231 | C7: =HARIAN!I11 -> 13 | D7: =HARIAN!P11 -> 169 | E7: =C7/B7 -> 0.056277056 | F7: =HARIAN!Q11 -> 0.82439024 | G7: =HARIAN!R11 -> 0.97126437 | H7: =HARIAN!S11 -> 0.98224852
A8: =HARIAN!C12 -> JATIM TIMUR | B8: =HARIAN!D12 -> 173 | C8: =HARIAN!I12 -> 9 | D8: =HARIAN!P12 -> 130 | E8: =C8/B8 -> 0.052023121 | F8: =HARIAN!Q12 -> 0.8125 | G8: =HARIAN!R12 -> 0.94202899 | H8: =HARIAN!S12 -> 1
A9: =HARIAN!C13 -> NUSA TENGGARA | B9: =HARIAN!D13 -> 210 | C9: =HARIAN!I13 -> 31 | D9: =HARIAN!P13 -> 121 | E9: =C9/B9 -> 0.14761905 | F9: =HARIAN!Q13 -> 0.71176471 | G9: =HARIAN!R13 -> 0.80666667 | H9: =HARIAN!S13 -> 0.76033058
A10: =HARIAN!C14 -> SURAMADU | B10: =HARIAN!D14 -> 274 | C10: =HARIAN!I14 -> 47 | D10: =HARIAN!P14 -> 164 | E10: =C10/B10 -> 0.17153285 | F10: =HARIAN!Q14 -> 0.74885845 | G10: =HARIAN!R14 -> 0.94252874 | H10: =HARIAN!S14 -> 0.98170732
A11: =HARIAN!C15 -> TOTAL | B11: =HARIAN!D15 -> 1014 | C11: =HARIAN!I15 -> 114 | D11: =HARIAN!P15 -> 644 | E11: =C11/B11 -> 0.11242604 | F11: =HARIAN!Q15 -> 0.75853946 | G11: =HARIAN!R15 -> 0.90322581 | H11: =HARIAN!S15 -> 0.9378882

Sheet LAPORAN
C1: ="PROVISIONING NEW SALES INDIBIZ TR3 JBN MTD H-1 "&TEXT(TODAY()-1,"YYYY-MM-DD ") -> PROVISIONING NEW SALES INDIBIZ TR3 JBN MTD H-1 2026-10-15
C2: ="PERIODE ORDER & PS : 2026-10-01 to "&TEXT(TODAY()-1,"YYYY-MM-DD ") -> PERIODE ORDER & PS : 2026-10-01 to 2026-10-15
C3: Last update proses : 16-10-2026 08:34:07 WIB (Source: ETL XPRO)
C5: WITEL | D5: (RE) | E5: INPROGRESS SC+QC1+FCC | F5: CANCEL | I5: REVOKE | J5: SURVEY NEW MANJA | K5: UN-SC | L5: OGP | P5: JML COMP (PS) | Q5: PS/RE (%) (Target 80%) | R5: PS/PI (%) (Target 94%) | S5: TTI COMPLY 1X 24 (%) (Target 94%)
F8: BY FCC | G8: KNDL PLGN | H8: KNDL NON PLGN | L8: PRE PI | M8: PI | N8: FALLOUT | O8: ACT COMP (QC2)
C9: BALI | D9: =HARIAN!D10 -> 126 | E9: =HARIAN!E10 -> 1 | F9: =HARIAN!F10 -> 7 | G9: =HARIAN!G10 -> 1 | H9: =HARIAN!H10 -> 11 | I9: =HARIAN!I10 -> 14 | J9: =HARIAN!J10 -> 5 | K9: =HARIAN!K10 -> 10 | ... S9: =HARIAN!S10 -> 0.91666667
C10: JATIM BARAT | D10: =HARIAN!D11 -> 231 | E10: =HARIAN!E11 -> 5 | F10: =HARIAN!F11 -> 5 | G10: =HARIAN!G11 -> 3 | H10: =HARIAN!H11 -> 8 | I10: =HARIAN!I11 -> 13 | J10: =HARIAN!J11 -> 14 | K10: =HARIAN!K11 -> 8 | ... S10: =HARIAN!S11 -> 0.98224852
C11: JATIM TIMUR | D11: =HARIAN!D12 -> 173 | E11: =HARIAN!E12 -> 4 | F11: =HARIAN!F12 -> 2 | G11: =HARIAN!G12 -> 5 | H11: =HARIAN!H12 -> 8 | I11: =HARIAN!I12 -> 9 | J11: =HARIAN!J12 -> 5 | K11: =HARIAN!K12 -> 2 | ... S11: =HARIAN!S12 -> 1
C12: NUSA TENGGARA | D12: =HARIAN!D13 -> 210 | E12: =HARIAN!E13 -> 6 | F12: =HARIAN!F13 -> 4 | G12: =HARIAN!G13 -> 2 | H12: =HARIAN!H13 -> 3 | I12: =HARIAN!I13 -> 31 | J12: =HARIAN!J13 -> 9 | K12: =HARIAN!K13 -> 5 | ... S12: =HARIAN!S13 -> 0.76033058
C13: SURAMADU | D13: =HARIAN!D14 -> 274 | E13: =HARIAN!E14 -> 11 | F13: =HARIAN!F14 -> 6 | G13: =HARIAN!G14 -> 1 | H13: =HARIAN!H14 -> 3 | I13: =HARIAN!I14 -> 47 | J13: =HARIAN!J14 -> 29 | K13: =HARIAN!K14 -> 2 | ... S13: =HARIAN!S14 -> 0.98170732
C14: TOTAL | D14: =SUM(D9:D13) -> 1014 | E14: =SUM(E9:E13) -> 27 | F14: =SUM(F9:F13) -> 24 | G14: =SUM(G9:G13) -> 12 | H14: =SUM(H9:H13) -> 33 | I14: =SUM(I9:I13) -> 114 | J14: =SUM(J9:J13) -> 62 | K14: =SUM(K9:K13) -> 27 | ... P14: =SUM(P9:P13) -> 644 | Q14: =HARIAN!Q15 -> 0.75853946 | R14: =HARIAN!R15 -> 0.90322581 | S14: =HARIAN!S15 -> 0.9378882
C16: Keterangan | D16: UIC | G16: * Target PS/PI Sesuai dengan Draft SLA MSA 2025 | L16: FORMULA
D17: Inputer, DIT, FCC | G17: 1. Time To Install (TTI) Comply Indibiz | 1x24 jam | L17: PI/RE : (Total PI + Total Fallout + Act Comp + Jumlah PS + Total Cancel) / Registered
D18: Order Cancel & Revoke | G18: 2. Fulfillment Guarantee (FFG) Indibiz | 60 hari | L18: PS/RE : PS / (Registered - Cancel by FCC - UNSC - Revoke)
D19: TA, BGESOPS, DAMAN, DIT | G19: 3. TTR Fulfillment Guarantee Indibiz | 3 jam | L19: PS/PI : PS / (Total PI + Total Fallout + Act Comp + Jumlah PS)
D20: Completed (PS) | G20: 4. PS to PI Ratio Indibiz Q3 88 % (Incremental)
D21: Performansi | G21: 5. Underspec warranty Indibiz | <= -25dBm
B23: =C1 -> PROVISIONING NEW SALES INDIBIZ TR3 JBN MTD H-1 2026-10-15
B24: =C2 -> PERIODE ORDER & PS : 2026-10-01 to 2026-10-15
B25: =C3 -> Last update proses : 16-10-2026 08:34:07 WIB (Source: ETL XPRO)
B28: WITEL | C28: TELDA | D28: (RE) | E28: INPROGRESS SC+QC1+FCC | F28: CANCEL | I28: REVOKE | J28: SURVEY NEW MANJA | K28: UN-SC | L28: OGP | P28: JML COMP (PS) | Q28: PS/RE (%) (Target 80%) | R28: PS/PI (%) (Target 94%) | S28: TTI COMPLY 1X 24 (%) (Target 94%)
F31: BY FCC | G31: KNDL PLGN | H31: KNDL NON PLGN | L31: PRE PI | M31: PI | N31: FALLOUT | O31: ACT COMP (QC2)
B32: BALI | C32: GIANYAR | D32: =HARIAN!D33 -> 12 | E32: =HARIAN!E33 -> 0 | F32: =HARIAN!F33 -> 0 | G32: =HARIAN!G33 -> 0 | H32: =HARIAN!H33 -> 0 | I32: =HARIAN!I33 -> 3 | J32: =HARIAN!J33 -> 0 | K32: =HARIAN!K33 -> 0 | ... P32: =HARIAN!P33 -> 9 | Q32: =T32 -> 1 | R32: =U32 -> 1 | S32: =VLOOKUP(C32,Sheet3!$A$19:$G$81,7,FALSE) -> 0.66666667 | T32: =P32/(D32-F32-K32-I32) -> 1 | U32: =P32/(M32+N32+O32+P32) -> 1
C33: TABANAN | D33: =HARIAN!D34+HARIAN!D39 -> 49 | E33: =HARIAN!E34+HARIAN!E39 -> 1 | F33: =HARIAN!F34+HARIAN!F39 -> 2 | G33: =HARIAN!G34+HARIAN!G39 -> 0 | H33: =HARIAN!H34+HARIAN!H39 -> 11 | I33: =HARIAN!I34+HARIAN!I39 -> 3 | J33: =HARIAN!J34+HARIAN!J39 -> 1 | K33: =HARIAN!K34+HARIAN!K39 -> 10 | ... P33: =HARIAN!P34+HARIAN!P39 -> 16 | Q33: =T33 -> 0.47058824 | R33: =U33 -> 0.76190476 | S33: =VLOOKUP(C33,Sheet3!$A$19:$G$81,7,FALSE) -> 0.93333333 | T33: =P33/(D33-F33-K33-I33) -> 0.47058824 | U33: =P33/(M33+N33+O33+P33) -> 0.76190476
C34: JIMBARAN | D34: =HARIAN!D35 -> 15 | E34: =HARIAN!E35 -> 0 | F34: =HARIAN!F35 -> 3 | G34: =HARIAN!G35 -> 0 | H34: =HARIAN!H35 -> 0 | I34: =HARIAN!I35 -> 2 | J34: =HARIAN!J35 -> 1 | K34: =HARIAN!K35 -> 0 | ... P34: =HARIAN!P35 -> 5 | Q34: =T34 -> 0.5 | R34: =U34 -> 0.55555556 | S34: =VLOOKUP(C34,Sheet3!$A$19:$G$81,7,FALSE) -> 0.8 | T34: =P34/(D34-F34-K34-I34) -> 0.5 | U34: =P34/(M34+N34+O34+P34) -> 0.55555556
C35: KLUNGKUNG | D35: =HARIAN!D36 -> 11 | E35: =HARIAN!E36 -> 0 | F35: =HARIAN!F36 -> 1 | G35: =HARIAN!G36 -> 0 | H35: =HARIAN!H36 -> 0 | I35: =HARIAN!I36 -> 1 | J35: =HARIAN!J36 -> 2 | K35: =HARIAN!K36 -> 0 | ... P35: =HARIAN!P36 -> 6 | Q35: =T35 -> 0.66666667 | R35: =U35 -> 0.85714286 | S35: =VLOOKUP(C35,Sheet3!$A$19:$G$81,7,FALSE) -> 1 | T35: =P35/(D35-F35-K35-I35) -> 0.66666667 | U35: =P35/(M35+N35+O35+P35) -> 0.85714286
C36: SANUR | D36: =HARIAN!D37 -> 14 | E36: =HARIAN!E37 -> 0 | F36: =HARIAN!F37 -> 1 | G36: =HARIAN!G37 -> 0 | H36: =HARIAN!H37 -> 0 | I36: =HARIAN!I37 -> 1 | J36: =HARIAN!J37 -> 1 | K36: =HARIAN!K37 -> 0 | ... P36: =HARIAN!P37 -> 10 | Q36: =T36 -> 0.83333333 | R36: =U36 -> 0.90909091 | S36: =VLOOKUP(C36,Sheet3!$A$19:$G$81,7,FALSE) -> 1 | T36: =P36/(D36-F36-K36-I36) -> 0.83333333 | U36: =P36/(M36+N36+O36+P36) -> 0.90909091
C37: SINGARAJA | D37: =HARIAN!D38 -> 7 | E37: =HARIAN!E38 -> 0 | F37: =HARIAN!F38 -> 0 | G37: =HARIAN!G38 -> 0 | H37: =HARIAN!H38 -> 0 | I37: =HARIAN!I38 -> 1 | J37: =HARIAN!J38 -> 0 | K37: =HARIAN!K38 -> 0 | ... P37: =HARIAN!P38 -> 5 | Q37: =T37 -> 0.83333333 | R37: =U37 -> 0.83333333 | S37: =VLOOKUP(C37,Sheet3!$A$19:$G$81,7,FALSE) -> 1 | T37: =P37/(D37-F37-K37-I37) -> 0.83333333 | U37: =P37/(M37+N37+O37+P37) -> 0.83333333
C38: UBUNG | D38: =HARIAN!D40 -> 18 | E38: =HARIAN!E40 -> 0 | F38: =HARIAN!F40 -> 0 | G38: =HARIAN!G40 -> 1 | H38: =HARIAN!H40 -> 0 | I38: =HARIAN!I40 -> 3 | J38: =HARIAN!J40 -> 0 | K38: =HARIAN!K40 -> 0 | ... P38: =HARIAN!P40 -> 9 | Q38: =T38 -> 0.6 | R38: =U38 -> 0.64285714 | S38: =VLOOKUP(C38,Sheet3!$A$19:$G$81,7,FALSE) -> 1 | T38: =P38/(D38-F38-K38-I38) -> 0.6 | U38: =P38/(M38+N38+O38+P38) -> 0.64285714
B39: JATIM BARAT | C39: BATU | D39: =HARIAN!D41 -> 31 | E39: =HARIAN!E41 -> 3 | F39: =HARIAN!F41 -> 0 | G39: =HARIAN!G41 -> 0 | H39: =HARIAN!H41 -> 3 | I39: =HARIAN!I41 -> 1 | J39: =HARIAN!J41 -> 8 | K39: =HARIAN!K41 -> 0 | ... P39: =HARIAN!P41 -> 16 | Q39: =T39 -> 0.53333333 | R39: =U39 -> 1 | S39: =VLOOKUP(C39,Sheet3!$A$19:$G$81,7,FALSE) -> 1 | T39: =P39/(D39-F39-K39-I39) -> 0.53333333 | U39: =P39/(M39+N39+O39+P39) -> 1
C40: BLITAR | D40: =HARIAN!D42+HARIAN!D52 -> 25 | E40: =HARIAN!E42+HARIAN!E52 -> 0 | F40: =HARIAN!F42+HARIAN!F52 -> 2 | G40: =HARIAN!G42+HARIAN!G52 -> 0 | H40: =HARIAN!H42+HARIAN!H52 -> 1 | I40: =HARIAN!I42+HARIAN!I52 -> 0 | J40: =HARIAN!J42+HARIAN!J52 -> 2 | K40: =HARIAN!K42+HARIAN!K52 -> 0 | ... P40: =HARIAN!P42+HARIAN!P52 -> 20 | Q40: =T40 -> 0.86956522 | R40: =U40 -> 1 | S40: =VLOOKUP(C40,Sheet3!$A$19:$G$81,7,FALSE) -> 1 | T40: =P40/(D40-F40-K40-I40) -> 0.86956522 | U40: =P40/(M40+N40+O40+P40) -> 1
C41: BOJONEGORO | D41: =HARIAN!D43+HARIAN!D51 -> 43 | E41: =HARIAN!E43+HARIAN!E51 -> 1 | F41: =HARIAN!F43+HARIAN!F51 -> 3 | G41: =HARIAN!G43+HARIAN!G51 -> 1 | H41: =HARIAN!H43+HARIAN!H51 -> 1 | I41: =HARIAN!I43+HARIAN!I51 -> 5 | J41: =HARIAN!J43+HARIAN!J51 -> 0 | K41: =HARIAN!K43+HARIAN!K51 -> 2 | ... P41: =HARIAN!P43+HARIAN!P51 -> 29 | Q41: =T41 -> 0.87878788 | R41: =U41 -> 0.96666667 | S41: =VLOOKUP(C41,Sheet3!$A$19:$G$81,7,FALSE) -> 1 | T41: =P41/(D41-F41-K41-I41) -> 0.87878788 | U41: =P41/(M41+N41+O41+P41) -> 0.96666667
C42: KEDIRI | D42: =HARIAN!D44 -> 33 | E42: =HARIAN!E44 -> 1 | F42: =HARIAN!F44 -> 0 | G42: =HARIAN!G44 -> 0 | H42: =HARIAN!H44 -> 1 | I42: =HARIAN!I44 -> 0 | J42: =HARIAN!J44 -> 0 | K42: =HARIAN!K44 -> 0 | ... P42: =HARIAN!P44 -> 30 | Q42: =T42 -> 0.90909091 | R42: =U42 -> 0.96774194 | S42: =VLOOKUP(C42,Sheet3!$A$19:$G$81,7,FALSE) -> 0.93333333 | T42: =P42/(D42-F42-K42-I42) -> 0.90909091 | U42: =P42/(M42+N42+O42+P42) -> 0.96774194
C43: MALANG | D43: =HARIAN!D45 -> 34 | E43: =HARIAN!E45 -> 0 | F43: =HARIAN!F45 -> 0 | G43: =HARIAN!G45 -> 0 | H43: =HARIAN!H45 -> 0 | I43: =HARIAN!I45 -> 3 | J43: =HARIAN!J45 -> 0 | K43: =HARIAN!K45 -> 0 | ... P43: =HARIAN!P45 -> 31 | Q43: =T43 -> 1 | R43: =U43 -> 1 | S43: =VLOOKUP(C43,Sheet3!$A$19:$G$81,7,FALSE) -> 1 | T43: =P43/(D43-F43-K43-I43) -> 1 | U43: =P43/(M43+N43+O43+P43) -> 1
C44: MADIUN | D44: =HARIAN!D46 -> 8 | E44: =HARIAN!E46 -> 0 | F44: =HARIAN!F46 -> 0 | G44: =HARIAN!G46 -> 0 | H44: =HARIAN!H46 -> 0 | I44: =HARIAN!I46 -> 0 | J44: =HARIAN!J46 -> 0 | K44: =HARIAN!K46 -> 0 | ... P44: =HARIAN!P46 -> 7 | Q44: =T44 -> 0.875 | R44: =U44 -> 1 | S44: =VLOOKUP(C44,Sheet3!$A$19:$G$81,7,FALSE) -> 1 | T44: =P44/(D44-F44-K44-I44) -> 0.875 | U44: =P44/(M44+N44+O44+P44) -> 1
C45: NGANJUK | D45: =HARIAN!D47 -> 20 | E45: =HARIAN!E47 -> 0 | F45: =HARIAN!F47 -> 0 | G45: =HARIAN!G47 -> 0 | H45: =HARIAN!H47 -> 1 | I45: =HARIAN!I47 -> 2 | J45: =HARIAN!J47 -> 1 | K45: =HARIAN!K47 -> 5 | ... P45: =HARIAN!P47 -> 9 | Q45: =T45 -> 0.69230769 | R45: =U45 -> 0.81818182 | S45: =VLOOKUP(C45,Sheet3!$A$19:$G$81,7,FALSE) -> 1 | T45: =P45/(D45-F45-K45-I45) -> 0.69230769 | U45: =P45/(M45+N45+O45+P45) -> 0.81818182
C46: MADIUN | D46: =HARIAN!D48 -> 8 | E46: =HARIAN!E48 -> 0 | F46: =HARIAN!F48 -> 0 | G46: =HARIAN!G48 -> 0 | H46: =HARIAN!H48 -> 0 | I46: =HARIAN!I48 -> 0 | J46: =HARIAN!J48 -> 1 | K46: =HARIAN!K48 -> 0 | ... P46: =HARIAN!P48 -> 6 | Q46: =T46 -> 0.75 | R46: =U46 -> 0.85714286 | S46: =VLOOKUP(C46,Sheet3!$A$19:$G$81,7,FALSE) -> 1 | T46: =P46/(D46-F46-K46-I46) -> 0.75 | U46: =P46/(M46+N46+O46+P46) -> 0.85714286
C47: PONOROGO | D47: =HARIAN!D49+HARIAN!D50 -> 29 | E47: =HARIAN!E49+HARIAN!E50 -> 0 | F47: =HARIAN!F49+HARIAN!F50 -> 0 | G47: =HARIAN!G49+HARIAN!G50 -> 2 | H47: =HARIAN!H49+HARIAN!H50 -> 1 | I47: =HARIAN!I49+HARIAN!I50 -> 2 | J47: =HARIAN!J49+HARIAN!J50 -> 2 | K47: =HARIAN!K49+HARIAN!K50 -> 1 | ... P47: =HARIAN!P49+HARIAN!P50 -> 21 | Q47: =T47 -> 0.80769231 | R47: =U47 -> 1 | S47: =VLOOKUP(C47,Sheet3!$A$19:$G$81,7,FALSE) -> 0.95238095 | T47: =P47/(D47-F47-K47-I47) -> 0.80769231 | U47: =P47/(M47+N47+O47+P47) -> 1
B48: JATIM TIMUR | C48: BANYUWANGI | D48: =HARIAN!D53+HARIAN!D62 -> 21 | E48: =HARIAN!E53+HARIAN!E62 -> 0 | F48: =HARIAN!F53+HARIAN!F62 -> 0 | G48: =HARIAN!G53+HARIAN!G62 -> 1 | H48: =HARIAN!H53+HARIAN!H62 -> 2 | I48: =HARIAN!I53+HARIAN!I62 -> 0 | J48: =HARIAN!J53+HARIAN!J62 -> 2 | K48: =HARIAN!K53+HARIAN!K62 -> 0 | ... P48: =HARIAN!P53+HARIAN!P62 -> 16 | Q48: =T48 -> 0.76190476 | R48: =U48 -> 1 | S48: =VLOOKUP(C48,Sheet3!$A$19:$G$81,7,FALSE) -> 1 | T48: =P48/(D48-F48-K48-I48) -> 0.76190476 | U48: =P48/(M48+N48+O48+P48) -> 1
C49: JEMBER | D49: =HARIAN!D54+HARIAN!D56 -> 22 | E49: =HARIAN!E54+HARIAN!E56 -> 0 | F49: =HARIAN!F54+HARIAN!F56 -> 0 | G49: =HARIAN!G54+HARIAN!G56 -> 0 | H49: =HARIAN!H54+HARIAN!H56 -> 1 | I49: =HARIAN!I54+HARIAN!I56 -> 0 | J49: =HARIAN!J54+HARIAN!J56 -> 0 | K49: =HARIAN!K54+HARIAN!K56 -> 0 | ... P49: =HARIAN!P54+HARIAN!P56 -> 20 | Q49: =T49 -> 0.90909091 | R49: =U49 -> 0.95238095 | S49: =VLOOKUP(C49,Sheet3!$A$19:$G$81,7,FALSE) -> 1 | T49: =P49/(D49-F49-K49-I49) -> 0.90909091 | U49: =P49/(M49+N49+O49+P49) -> 0.95238095
...

Sheet Sheet4
C1: PROVISIONING NEW SALES INDIBIZ TR3 JBN MTD H-1
C2: =LAPORAN!C2 -> PERIODE ORDER & PS : 2026-10-01 to 2026-10-15
C3: =LAPORAN!C3 -> Last update proses : 16-10-2026 08:34:07 WIB (Source: ETL XPRO)
C5: WITEL | D5: REGISTER (RE) | E5: SURVEY NEW MANJA | F5: UN-SC | G5: PRE PI | H5: PI | I5: TOTAL FALLOUT | J5: QC2 | K5: PS | L5: PS/RE (%) (Target 80%) | M5: PS/PI (%) (Target 94%) | N5: TTI COMPLY 1X 24 (%) (Target 94%)
C6: =[1]LAPORAN!C9 -> BALI | D6: =LAPORAN!D9 -> 126 | E6: =LAPORAN!J9 -> 5 | F6: =LAPORAN!K9 -> 10 | G6: =LAPORAN!L9 -> 0 | H6: =LAPORAN!M9 -> 12 | I6: =LAPORAN!N9 -> 4 | J6: =LAPORAN!O9 -> 1 | K6: =LAPORAN!P9 -> 60 | L6: =LAPORAN!Q9 -> 0.63157895 | ... N6: =LAPORAN!S9 -> 0.91666667
C7: =[1]LAPORAN!C10 -> JATIM BARAT | D7: =LAPORAN!D10 -> 231 | E7: =LAPORAN!J10 -> 14 | F7: =LAPORAN!K10 -> 8 | G7: =LAPORAN!L10 -> 0 | H7: =LAPORAN!M10 -> 1 | I7: =LAPORAN!N10 -> 1 | J7: =LAPORAN!O10 -> 3 | K7: =LAPORAN!P10 -> 169 | L7: =LAPORAN!Q10 -> 0.82439024 | ... N7: =LAPORAN!S10 -> 0.98224852
C8: =[1]LAPORAN!C11 -> JATIM TIMUR | D8: =LAPORAN!D11 -> 173 | E8: =LAPORAN!J11 -> 5 | F8: =LAPORAN!K11 -> 2 | G8: =LAPORAN!L11 -> 0 | H8: =LAPORAN!M11 -> 1 | I8: =LAPORAN!N11 -> 2 | J8: =LAPORAN!O11 -> 5 | K8: =LAPORAN!P11 -> 130 | L8: =LAPORAN!Q11 -> 0.8125 | ... N8: =LAPORAN!S11 -> 1
C9: =[1]LAPORAN!C12 -> NUSA TENGGARA | D9: =LAPORAN!D12 -> 210 | E9: =LAPORAN!J12 -> 9 | F9: =LAPORAN!K12 -> 5 | G9: =LAPORAN!L12 -> 1 | H9: =LAPORAN!M12 -> 19 | I9: =LAPORAN!N12 -> 5 | J9: =LAPORAN!O12 -> 5 | K9: =LAPORAN!P12 -> 121 | L9: =LAPORAN!Q12 -> 0.71176471 | ... N9: =LAPORAN!S12 -> 0.76033058
C10: =[1]LAPORAN!C13 -> SURAMADU | D10: =LAPORAN!D13 -> 274 | E10: =LAPORAN!J13 -> 29 | F10: =LAPORAN!K13 -> 2 | G10: =LAPORAN!L13 -> 1 | H10: =LAPORAN!M13 -> 1 | I10: =LAPORAN!N13 -> 5 | J10: =LAPORAN!O13 -> 4 | K10: =LAPORAN!P13 -> 164 | L10: =LAPORAN!Q13 -> 0.74885845 | ... N10: =LAPORAN!S13 -> 0.98170732
C11: =[1]LAPORAN!C14 -> TOTAL | D11: =LAPORAN!D14 -> 1014 | E11: =LAPORAN!J14 -> 62 | F11: =LAPORAN!K14 -> 27 | G11: =LAPORAN!L14 -> 2 | H11: =LAPORAN!M14 -> 34 | I11: =LAPORAN!N14 -> 17 | J11: =LAPORAN!O14 -> 18 | K11: =LAPORAN!P14 -> 644 | L11: =LAPORAN!Q14 -> 0.75853946 | ... N11: =LAPORAN!S14 -> 0.9378882

Sheet LOOKUP  telda
C1: HARIAN
C3: WITEL | D3: PRE PI | E3: REGISTERED (RE) | F3: INPROGRESS SC | G3: QC1 | H3: FCC | I3: CANCEL BY FCC | J3: SURVEY NEW MANJA | K3: UN-SC | L3: OGP | Z3: JML COMP (PS) | AA3: CANCEL | AE3: TOTAL CANCEL | AF3: REVOKE | AG3: PI/RE (%) | AH3: PS/RE (%) | AI3: PS/PI (%)
L4: PRE PI | M4: PI | P4: TOTAL PI | Q4: FALLOUT | X4: TOTAL FALLOUT | Y4: ACT COMP (QC2)
Q5: WFM | U5: UIM | V5: ASP | W5: OSM
M6: < 1 HARI | N6: 1 - 3 HARI | O6: > 3 HARI | Q6: KNDL PLGN | R6: KNDL TEKNIS | S6: KNDL SYS | T6: OTHERS | AA6: KNDL PLGN | AB6: KNDL TEKNIS | AC6: KNDL SYS | AD6: OTHERS
B7: BALI | C7: GIANYAR | D7: =IFERROR(VLOOKUP(C7,'COPY DATA XPRO'!$C$7:$AI$58,2,FALSE),0) -> 0 | E7: =IFERROR(VLOOKUP(C7,'COPY DATA XPRO'!$C$7:$AI$58,3,FALSE),0) -> 12 | F7: =IFERROR(VLOOKUP(C7,'COPY DATA XPRO'!$C$7:$AI$58,4,FALSE),0) -> 0 | G7: =IFERROR(VLOOKUP(C7,'COPY DATA XPRO'!$C$7:$AI$58,5,FALSE),0) -> 0 | H7: =IFERROR(VLOOKUP(C7,'COPY DATA XPRO'!$C$7:$AI$58,6,FALSE),0) -> 0 | I7: =IFERROR(VLOOKUP(C7,'COPY DATA XPRO'!$C$7:$AI$58,7,FALSE),0) -> 0 | J7: =IFERROR(VLOOKUP(C7,'COPY DATA XPRO'!$C$7:$AI$58,8,FALSE),0) -> 0 | K7: =IFERROR(VLOOKUP(C7,'COPY DATA XPRO'!$C$7:$AI$58,9,FALSE),0) -> 0 | L7: =IFERROR(VLOOKUP(C7,'COPY DATA XPRO'!$C$7:$AI$58,10,FALSE),0) -> 0 | M7: =IFERROR(VLOOKUP(C7,'COPY DATA XPRO'!$C$7:$AI$58,11,FALSE),0) -> 0 | N7: =IFERROR(VLOOKUP(C7,'COPY DATA XPRO'!$C$7:$AI$58,12,FALSE),0) -> 0 | O7: =IFERROR(VLOOKUP(C7,'COPY DATA XPRO'!$C$7:$AI$58,13,FALSE),0) -> 0 | P7: =IFERROR(VLOOKUP(C7,'COPY DATA XPRO'!$C$7:$AI$58,14,FALSE),0) -> 0 | Q7: =IFERROR(VLOOKUP(C7,'COPY DATA XPRO'!$C$7:$AI$58,15,FALSE),0) -> 0 | R7: =IFERROR(VLOOKUP(C7,'COPY DATA XPRO'!$C$7:$AI$58,16,FALSE),0) -> 0 | S7: =IFERROR(VLOOKUP(C7,'COPY DATA XPRO'!$C$7:$AI$58,17,FALSE),0) -> 0 | T7: =IFERROR(VLOOKUP(C7,'COPY DATA XPRO'!$C$7:$AI$58,18,FALSE),0) -> 0 | U7: =IFERROR(VLOOKUP(C7,'COPY DATA XPRO'!$C$7:$AI$58,19,FALSE),0) -> 0 | V7: =IFERROR(VLOOKUP(C7,'COPY DATA XPRO'!$C$7:$AI$58,20,FALSE),0) -> 0 | W7: =IFERROR(VLOOKUP(C7,'COPY DATA XPRO'!$C$7:$AI$58,21,FALSE),0) -> 0 | X7: =IFERROR(VLOOKUP(C7,'COPY DATA XPRO'!$C$7:$AI$58,22,FALSE),0) -> 0 | Y7: =IFERROR(VLOOKUP(C7,'COPY DATA XPRO'!$C$7:$AI$58,23,FALSE),0) -> 0 | Z7: =IFERROR(VLOOKUP(C7,'COPY DATA XPRO'!$C$7:$AI$58,24,FALSE),0) -> 9 | AA7: =IFERROR(VLOOKUP(C7,'COPY DATA XPRO'!$C$7:$AI$58,25,FALSE),0) -> 0 | AB7: =IFERROR(VLOOKUP(C7,'COPY DATA XPRO'!$C$7:$AI$58,26,FALSE),0) -> 0 | AC7: =IFERROR(VLOOKUP(C7,'COPY DATA XPRO'!$C$7:$AI$58,27,FALSE),0) -> 0 | AD7: =IFERROR(VLOOKUP(C7,'COPY DATA XPRO'!$C$7:$AI$58,28,FALSE),0) -> 0 | AE7: =IFERROR(VLOOKUP(C7,'COPY DATA XPRO'!$C$7:$AI$58,29,FALSE),0) -> 0 | AF7: =IFERROR(VLOOKUP(C7,'COPY DATA XPRO'!$C$7:$AI$58,30,FALSE),0) -> 3 | AG7: =IFERROR(VLOOKUP(C7,'COPY DATA XPRO'!$C$7:$AI$58,31,FALSE),0) -> 75 | AH7: =IFERROR(VLOOKUP(C7,'COPY DATA XPRO'!$C$7:$AI$58,32,FALSE),0) -> 100 | AI7: =IFERROR(VLOOKUP(C7,'COPY DATA XPRO'!$C$7:$AI$58,33,FALSE),0) -> 100
C8: JEMBRANA | D8: =IFERROR(VLOOKUP(C8,'COPY DATA XPRO'!$C$7:$AI$58, 2, FALSE), 0) -> 0 | E8: =IFERROR(VLOOKUP(C8,'COPY DATA XPRO'!$C$7:$AI$58,3,FALSE),0) -> 1 | F8: =IFERROR(VLOOKUP(C8,'COPY DATA XPRO'!$C$7:$AI$58,4,FALSE),0) -> 0 | G8: =IFERROR(VLOOKUP(C8,'COPY DATA XPRO'!$C$7:$AI$58,5,FALSE),0) -> 0 | H8: =IFERROR(VLOOKUP(C8,'COPY DATA XPRO'!$C$7:$AI$58,6,FALSE),0) -> 0 | I8: =IFERROR(VLOOKUP(C8,'COPY DATA XPRO'!$C$7:$AI$58,7,FALSE),0) -> 0 | J8: =IFERROR(VLOOKUP(C8,'COPY DATA XPRO'!$C$7:$AI$58,8,FALSE),0) -> 0 | K8: =IFERROR(VLOOKUP(C8,'COPY DATA XPRO'!$C$7:$AI$58,9,FALSE),0) -> 0 | L8: =IFERROR(VLOOKUP(C8,'COPY DATA XPRO'!$C$7:$AI$58,10,FALSE),0) -> 0 | M8: =IFERROR(VLOOKUP(C8,'COPY DATA XPRO'!$C$7:$AI$58,11,FALSE),0) -> 0 | N8: =IFERROR(VLOOKUP(C8,'COPY DATA XPRO'!$C$7:$AI$58,12,FALSE),0) -> 0 | O8: =IFERROR(VLOOKUP(C8,'COPY DATA XPRO'!$C$7:$AI$58,13,FALSE),0) -> 0 | P8: =IFERROR(VLOOKUP(C8,'COPY DATA XPRO'!$C$7:$AI$58,14,FALSE),0) -> 0 | Q8: =IFERROR(VLOOKUP(C8,'COPY DATA XPRO'!$C$7:$AI$58,15,FALSE),0) -> 0 | R8: =IFERROR(VLOOKUP(C8,'COPY DATA XPRO'!$C$7:$AI$58,16,FALSE),0) -> 0 | S8: =IFERROR(VLOOKUP(C8,'COPY DATA XPRO'!$C$7:$AI$58,17,FALSE),0) -> 0 | T8: =IFERROR(VLOOKUP(C8,'COPY DATA XPRO'!$C$7:$AI$58,18,FALSE),0) -> 0 | U8: =IFERROR(VLOOKUP(C8,'COPY DATA XPRO'!$C$7:$AI$58,19,FALSE),0) -> 0 | V8: =IFERROR(VLOOKUP(C8,'COPY DATA XPRO'!$C$7:$AI$58,20,FALSE),0) -> 0 | W8: =IFERROR(VLOOKUP(C8,'COPY DATA XPRO'!$C$7:$AI$58,21,FALSE),0) -> 0 | X8: =IFERROR(VLOOKUP(C8,'COPY DATA XPRO'!$C$7:$AI$58,22,FALSE),0) -> 0 | Y8: =IFERROR(VLOOKUP(C8,'COPY DATA XPRO'!$C$7:$AI$58,23,FALSE),0) -> 0 | Z8: =IFERROR(VLOOKUP(C8,'COPY DATA XPRO'!$C$7:$AI$58,24,FALSE),0) -> 1 | AA8: =IFERROR(VLOOKUP(C8,'COPY DATA XPRO'!$C$7:$AI$58,25,FALSE),0) -> 0 | AB8: =IFERROR(VLOOKUP(C8,'COPY DATA XPRO'!$C$7:$AI$58,26,FALSE),0) -> 0 | AC8: =IFERROR(VLOOKUP(C8,'COPY DATA XPRO'!$C$7:$AI$58,27,FALSE),0) -> 0 | AD8: =IFERROR(VLOOKUP(C8,'COPY DATA XPRO'!$C$7:$AI$58,28,FALSE),0) -> 0 | AE8: =IFERROR(VLOOKUP(C8,'COPY DATA XPRO'!$C$7:$AI$58,29,FALSE),0) -> 0 | AF8: =IFERROR(VLOOKUP(C8,'COPY DATA XPRO'!$C$7:$AI$58,30,FALSE),0) -> 0 | AG8: =IFERROR(VLOOKUP(C8,'COPY DATA XPRO'!$C$7:$AI$58,31,FALSE),0) -> 100 | AH8: =IFERROR(VLOOKUP(C8,'COPY DATA XPRO'!$C$7:$AI$58,32,FALSE),0) -> 100 | AI8: =IFERROR(VLOOKUP(C8,'COPY DATA XPRO'!$C$7:$AI$58,33,FALSE),0) -> 100
C9: JIMBARAN | D9: =IFERROR(VLOOKUP(C9,'COPY DATA XPRO'!$C$7:$AI$58,2,FALSE),0) -> 0 | E9: =IFERROR(VLOOKUP(C9,'COPY DATA XPRO'!$C$7:$AI$58,3,FALSE),0) -> 15 | F9: =IFERROR(VLOOKUP(C9,'COPY DATA XPRO'!$C$7:$AI$58,4,FALSE),0) -> 0 | G9: =IFERROR(VLOOKUP(C9,'COPY DATA XPRO'!$C$7:$AI$58,5,FALSE),0) -> 0 | H9: =IFERROR(VLOOKUP(C9,'COPY DATA XPRO'!$C$7:$AI$58,6,FALSE),0) -> 0 | I9: =IFERROR(VLOOKUP(C9,'COPY DATA XPRO'!$C$7:$AI$58,7,FALSE),0) -> 3 | J9: =IFERROR(VLOOKUP(C9,'COPY DATA XPRO'!$C$7:$AI$58,8,FALSE),0) -> 1 | K9: =IFERROR(VLOOKUP(C9,'COPY DATA XPRO'!$C$7:$AI$58,9,FALSE),0) -> 0 | L9: =IFERROR(VLOOKUP(C9,'COPY DATA XPRO'!$C$7:$AI$58,10,FALSE),0) -> 0 | M9: =IFERROR(VLOOKUP(C9,'COPY DATA XPRO'!$C$7:$AI$58,11,FALSE),0) -> 0 | N9: =IFERROR(VLOOKUP(C9,'COPY DATA XPRO'!$C$7:$AI$58,12,FALSE),0) -> 0 | O9: =IFERROR(VLOOKUP(C9,'COPY DATA XPRO'!$C$7:$AI$58,13,FALSE),0) -> 3 | P9: =IFERROR(VLOOKUP(C9,'COPY DATA XPRO'!$C$7:$AI$58,14,FALSE),0) -> 3 | Q9: =IFERROR(VLOOKUP(C9,'COPY DATA XPRO'!$C$7:$AI$58,15,FALSE),0) -> 1 | R9: =IFERROR(VLOOKUP(C9,'COPY DATA XPRO'!$C$7:$AI$58,16,FALSE),0) -> 0 | S9: =IFERROR(VLOOKUP(C9,'COPY DATA XPRO'!$C$7:$AI$58,17,FALSE),0) -> 0 | T9: =IFERROR(VLOOKUP(C9,'COPY DATA XPRO'!$C$7:$AI$58,18,FALSE),0) -> 0 | U9: =IFERROR(VLOOKUP(C9,'COPY DATA XPRO'!$C$7:$AI$58,19,FALSE),0) -> 0 | V9: =IFERROR(VLOOKUP(C9,'COPY DATA XPRO'!$C$7:$AI$58,20,FALSE),0) -> 0 | W9: =IFERROR(VLOOKUP(C9,'COPY DATA XPRO'!$C$7:$AI$58,21,FALSE),0) -> 0 | X9: =IFERROR(VLOOKUP(C9,'COPY DATA XPRO'!$C$7:$AI$58,22,FALSE),0) -> 1 | Y9: =IFERROR(VLOOKUP(C9,'COPY DATA XPRO'!$C$7:$AI$58,23,FALSE),0) -> 0 | Z9: =IFERROR(VLOOKUP(C9,'COPY DATA XPRO'!$C$7:$AI$58,24,FALSE),0) -> 5 | AA9: =IFERROR(VLOOKUP(C9,'COPY DATA XPRO'!$C$7:$AI$58,25,FALSE),0) -> 0 | AB9: =IFERROR(VLOOKUP(C9,'COPY DATA XPRO'!$C$7:$AI$58,26,FALSE),0) -> 0 | AC9: =IFERROR(VLOOKUP(C9,'COPY DATA XPRO'!$C$7:$AI$58,27,FALSE),0) -> 0 | AD9: =IFERROR(VLOOKUP(C9,'COPY DATA XPRO'!$C$7:$AI$58,28,FALSE),0) -> 0 | AE9: =IFERROR(VLOOKUP(C9,'COPY DATA XPRO'!$C$7:$AI$58,29,FALSE),0) -> 0 | AF9: =IFERROR(VLOOKUP(C9,'COPY DATA XPRO'!$C$7:$AI$58,30,FALSE),0) -> 2 | AG9: =IFERROR(VLOOKUP(C9,'COPY DATA XPRO'!$C$7:$AI$58,31,FALSE),0) -> 60 | AH9: =IFERROR(VLOOKUP(C9,'COPY DATA XPRO'!$C$7:$AI$58,32,FALSE),0) -> 50 | AI9: =IFERROR(VLOOKUP(C9,'COPY DATA XPRO'!$C$7:$AI$58,33,FALSE),0) -> 55.56
C10: KLUNGKUNG | D10: =IFERROR(VLOOKUP(C10,'COPY DATA XPRO'!$C$7:$AI$58,2,FALSE),0) -> 0 | E10: =IFERROR(VLOOKUP(C10,'COPY DATA XPRO'!$C$7:$AI$58,3,FALSE),0) -> 11 | F10: =IFERROR(VLOOKUP(C10,'COPY DATA XPRO'!$C$7:$AI$58,4,FALSE),0) -> 0 | G10: =IFERROR(VLOOKUP(C10,'COPY DATA XPRO'!$C$7:$AI$58,5,FALSE),0) -> 0 | H10: =IFERROR(VLOOKUP(C10,'COPY DATA XPRO'!$C$7:$AI$58,6,FALSE),0) -> 0 | I10: =IFERROR(VLOOKUP(C10,'COPY DATA XPRO'!$C$7:$AI$58,7,FALSE),0) -> 1 | J10: =IFERROR(VLOOKUP(C10,'COPY DATA XPRO'!$C$7:$AI$58,8,FALSE),0) -> 2 | K10: =IFERROR(VLOOKUP(C10,'COPY DATA XPRO'!$C$7:$AI$58,9,FALSE),0) -> 0 | L10: =IFERROR(VLOOKUP(C10,'COPY DATA XPRO'!$C$7:$AI$58,10,FALSE),0) -> 0 | M10: =IFERROR(VLOOKUP(C10,'COPY DATA XPRO'!$C$7:$AI$58,11,FALSE),0) -> 0 | N10: =IFERROR(VLOOKUP(C10,'COPY DATA XPRO'!$C$7:$AI$58,12,FALSE),0) -> 1 | O10: =IFERROR(VLOOKUP(C10,'COPY DATA XPRO'!$C$7:$AI$58,13,FALSE),0) -> 0 | P10: =IFERROR(VLOOKUP(C10,'COPY DATA XPRO'!$C$7:$AI$58,14,FALSE),0) -> 1 | Q10: =IFERROR(VLOOKUP(C10,'COPY DATA XPRO'!$C$7:$AI$58,15,FALSE),0) -> 0 | R10: =IFERROR(VLOOKUP(C10,'COPY DATA XPRO'!$C$7:$AI$58,16,FALSE),0) -> 0 | S10: =IFERROR(VLOOKUP(C10,'COPY DATA XPRO'!$C$7:$AI$58,17,FALSE),0) -> 0 | T10: =IFERROR(VLOOKUP(C10,'COPY DATA XPRO'!$C$7:$AI$58,18,FALSE),0) -> 0 | U10: =IFERROR(VLOOKUP(C10,'COPY DATA XPRO'!$C$7:$AI$58,19,FALSE),0) -> 0 | V10: =IFERROR(VLOOKUP(C10,'COPY DATA XPRO'!$C$7:$AI$58,20,FALSE),0) -> 0 | W10: =IFERROR(VLOOKUP(C10,'COPY DATA XPRO'!$C$7:$AI$58,21,FALSE),0) -> 0 | X10: =IFERROR(VLOOKUP(C10,'COPY DATA XPRO'!$C$7:$AI$58,22,FALSE),0) -> 0 | Y10: =IFERROR(VLOOKUP(C10,'COPY DATA XPRO'!$C$7:$AI$58,23,FALSE),0) -> 0 | Z10: =IFERROR(VLOOKUP(C10,'COPY DATA XPRO'!$C$7:$AI$58,24,FALSE),0) -> 6 | AA10: =IFERROR(VLOOKUP(C10,'COPY DATA XPRO'!$C$7:$AI$58,25,FALSE),0) -> 0 | AB10: =IFERROR(VLOOKUP(C10,'COPY DATA XPRO'!$C$7:$AI$58,26,FALSE),0) -> 0 | AC10: =IFERROR(VLOOKUP(C10,'COPY DATA XPRO'!$C$7:$AI$58,27,FALSE),0) -> 0 | AD10: =IFERROR(VLOOKUP(C10,'COPY DATA XPRO'!$C$7:$AI$58,28,FALSE),0) -> 0 | AE10: =IFERROR(VLOOKUP(C10,'COPY DATA XPRO'!$C$7:$AI$58,29,FALSE),0) -> 0 | AF10: =IFERROR(VLOOKUP(C10,'COPY DATA XPRO'!$C$7:$AI$58,30,FALSE),0) -> 1 | AG10: =IFERROR(VLOOKUP(C10,'COPY DATA XPRO'!$C$7:$AI$58,31,FALSE),0) -> 63.64 | AH10: =IFERROR(VLOOKUP(C10,'COPY DATA XPRO'!$C$7:$AI$58,32,FALSE),0) -> 66.67 | AI10: =IFERROR(VLOOKUP(C10,'COPY DATA XPRO'!$C$7:$AI$58,33,FALSE),0) -> 85.71
C11: SANUR | D11: =IFERROR(VLOOKUP(C11,'COPY DATA XPRO'!$C$7:$AI$58,2,FALSE),0) -> 0 | E11: =IFERROR(VLOOKUP(C11,'COPY DATA XPRO'!$C$7:$AI$58,3,FALSE),0) -> 14 | F11: =IFERROR(VLOOKUP(C11,'COPY DATA XPRO'!$C$7:$AI$58,4,FALSE),0) -> 0 | G11: =IFERROR(VLOOKUP(C11,'COPY DATA XPRO'!$C$7:$AI$58,5,FALSE),0) -> 0 | H11: =IFERROR(VLOOKUP(C11,'COPY DATA XPRO'!$C$7:$AI$58,6,FALSE),0) -> 0 | I11: =IFERROR(VLOOKUP(C11,'COPY DATA XPRO'!$C$7:$AI$58,7,FALSE),0) -> 1 | J11: =IFERROR(VLOOKUP(C11,'COPY DATA XPRO'!$C$7:$AI$58,8,FALSE),0) -> 1 | K11: =IFERROR(VLOOKUP(C11,'COPY DATA XPRO'!$C$7:$AI$58,9,FALSE),0) -> 0 | L11: =IFERROR(VLOOKUP(C11,'COPY DATA XPRO'!$C$7:$AI$58,10,FALSE),0) -> 0 | M11: =IFERROR(VLOOKUP(C11,'COPY DATA XPRO'!$C$7:$AI$58,11,FALSE),0) -> 0 | N11: =IFERROR(VLOOKUP(C11,'COPY DATA XPRO'!$C$7:$AI$58,12,FALSE),0) -> 0 | O11: =IFERROR(VLOOKUP(C11,'COPY DATA XPRO'!$C$7:$AI$58,13,FALSE),0) -> 0 | P11: =IFERROR(VLOOKUP(C11,'COPY DATA XPRO'!$C$7:$AI$58,14,FALSE),0) -> 0 | Q11: =IFERROR(VLOOKUP(C11,'COPY DATA XPRO'!$C$7:$AI$58,15,FALSE),0) -> 0 | R11: =IFERROR(VLOOKUP(C11,'COPY DATA XPRO'!$C$7:$AI$58,16,FALSE),0) -> 0 | S11: =IFERROR(VLOOKUP(C11,'COPY DATA XPRO'!$C$7:$AI$58,17,FALSE),0) -> 0 | T11: =IFERROR(VLOOKUP(C11,'COPY DATA XPRO'!$C$7:$AI$58,18,FALSE),0) -> 0 | U11: =IFERROR(VLOOKUP(C11,'COPY DATA XPRO'!$C$7:$AI$58,19,FALSE),0) -> 0 | V11: =IFERROR(VLOOKUP(C11,'COPY DATA XPRO'!$C$7:$AI$58,20,FALSE),0) -> 0 | W11: =IFERROR(VLOOKUP(C11,'COPY DATA XPRO'!$C$7:$AI$58,21,FALSE),0) -> 0 | X11: =IFERROR(VLOOKUP(C11,'COPY DATA XPRO'!$C$7:$AI$58,22,FALSE),0) -> 0 | Y11: =IFERROR(VLOOKUP(C11,'COPY DATA XPRO'!$C$7:$AI$58,23,FALSE),0) -> 1 | Z11: =IFERROR(VLOOKUP(C11,'COPY DATA XPRO'!$C$7:$AI$58,24,FALSE),0) -> 10 | AA11: =IFERROR(VLOOKUP(C11,'COPY DATA XPRO'!$C$7:$AI$58,25,FALSE),0) -> 0 | AB11: =IFERROR(VLOOKUP(C11,'COPY DATA XPRO'!$C$7:$AI$58,26,FALSE),0) -> 0 | AC11: =IFERROR(VLOOKUP(C11,'COPY DATA XPRO'!$C$7:$AI$58,27,FALSE),0) -> 0 | AD11: =IFERROR(VLOOKUP(C11,'COPY DATA XPRO'!$C$7:$AI$58,28,FALSE),0) -> 0 | AE11: =IFERROR(VLOOKUP(C11,'COPY DATA XPRO'!$C$7:$AI$58,29,FALSE),0) -> 0 | AF11: =IFERROR(VLOOKUP(C11,'COPY DATA XPRO'!$C$7:$AI$58,30,FALSE),0) -> 1 | AG11: =IFERROR(VLOOKUP(C11,'COPY DATA XPRO'!$C$7:$AI$58,31,FALSE),0) -> 78.57 | AH11: =IFERROR(VLOOKUP(C11,'COPY DATA XPRO'!$C$7:$AI$58,32,FALSE),0) -> 83.33 | AI11: =IFERROR(VLOOKUP(C11,'COPY DATA XPRO'!$C$7:$AI$58,33,FALSE),0) -> 90.91
C12: SINGARAJA | D12: =IFERROR(VLOOKUP(C12,'COPY DATA XPRO'!$C$7:$AI$58,2,FALSE),0) -> 0 | E12: =IFERROR(VLOOKUP(C12,'COPY DATA XPRO'!$C$7:$AI$58,3,FALSE),0) -> 7 | F12: =IFERROR(VLOOKUP(C12,'COPY DATA XPRO'!$C$7:$AI$58,4,FALSE),0) -> 0 | G12: =IFERROR(VLOOKUP(C12,'COPY DATA XPRO'!$C$7:$AI$58,5,FALSE),0) -> 0 | H12: =IFERROR(VLOOKUP(C12,'COPY DATA XPRO'!$C$7:$AI$58,6,FALSE),0) -> 0 | I12: =IFERROR(VLOOKUP(C12,'COPY DATA XPRO'!$C$7:$AI$58,7,FALSE),0) -> 0 | J12: =IFERROR(VLOOKUP(C12,'COPY DATA XPRO'!$C$7:$AI$58,8,FALSE),0) -> 0 | K12: =IFERROR(VLOOKUP(C12,'COPY DATA XPRO'!$C$7:$AI$58,9,FALSE),0) -> 0 | L12: =IFERROR(VLOOKUP(C12,'COPY DATA XPRO'!$C$7:$AI$58,10,FALSE),0) -> 0 | M12: =IFERROR(VLOOKUP(C12,'COPY DATA XPRO'!$C$7:$AI$58,11,FALSE),0) -> 0 | N12: =IFERROR(VLOOKUP(C12,'COPY DATA XPRO'!$C$7:$AI$58,12,FALSE),0) -> 0 | O12: =IFERROR(VLOOKUP(C12,'COPY DATA XPRO'!$C$7:$AI$58,13,FALSE),0) -> 1 | P12: =IFERROR(VLOOKUP(C12,'COPY DATA XPRO'!$C$7:$AI$58,14,FALSE),0) -> 1 | Q12: =IFERROR(VLOOKUP(C12,'COPY DATA XPRO'!$C$7:$AI$58,15,FALSE),0) -> 0 | R12: =IFERROR(VLOOKUP(C12,'COPY DATA XPRO'!$C$7:$AI$58,16,FALSE),0) -> 0 | S12: =IFERROR(VLOOKUP(C12,'COPY DATA XPRO'!$C$7:$AI$58,17,FALSE),0) -> 0 | T12: =IFERROR(VLOOKUP(C12,'COPY DATA XPRO'!$C$7:$AI$58,18,FALSE),0) -> 0 | U12: =IFERROR(VLOOKUP(C12,'COPY DATA XPRO'!$C$7:$AI$58,19,FALSE),0) -> 0 | V12: =IFERROR(VLOOKUP(C12,'COPY DATA XPRO'!$C$7:$AI$58,20,FALSE),0) -> 0 | W12: =IFERROR(VLOOKUP(C12,'COPY DATA XPRO'!$C$7:$AI$58,21,FALSE),0) -> 0 | X12: =IFERROR(VLOOKUP(C12,'COPY DATA XPRO'!$C$7:$AI$58,22,FALSE),0) -> 0 | Y12: =IFERROR(VLOOKUP(C12,'COPY DATA XPRO'!$C$7:$AI$58,23,FALSE),0) -> 0 | Z12: =IFERROR(VLOOKUP(C12,'COPY DATA XPRO'!$C$7:$AI$58,24,FALSE),0) -> 5 | AA12: =IFERROR(VLOOKUP(C12,'COPY DATA XPRO'!$C$7:$AI$58,25,FALSE),0) -> 0 | AB12: =IFERROR(VLOOKUP(C12,'COPY DATA XPRO'!$C$7:$AI$58,26,FALSE),0) -> 0 | AC12: =IFERROR(VLOOKUP(C12,'COPY DATA XPRO'!$C$7:$AI$58,27,FALSE),0) -> 0 | AD12: =IFERROR(VLOOKUP(C12,'COPY DATA XPRO'!$C$7:$AI$58,28,FALSE),0) -> 0 | AE12: =IFERROR(VLOOKUP(C12,'COPY DATA XPRO'!$C$7:$AI$58,29,FALSE),0) -> 0 | AF12: =IFERROR(VLOOKUP(C12,'COPY DATA XPRO'!$C$7:$AI$58,30,FALSE),0) -> 1 | AG12: =IFERROR(VLOOKUP(C12,'COPY DATA XPRO'!$C$7:$AI$58,31,FALSE),0) -> 85.71 | AH12: =IFERROR(VLOOKUP(C12,'COPY DATA XPRO'!$C$7:$AI$58,32,FALSE),0) -> 83.33 | AI12: =IFERROR(VLOOKUP(C12,'COPY DATA XPRO'!$C$7:$AI$58,33,FALSE),0) -> 83.33
